Workbook

Sheet Processed Data
A1: Trial 20 (Feb 2026 - Feb 2026) | BU1: Drug Type
G2: Quantity Billed = BestRX | R2: Package Size Billed = Quantity Billed(BestRx) ÷ Package Size | AC2: Package Size Difference = Total Packages Purchased(Vendors) − Package Size Billed(BestRx) | AN2: Actual $ Paid by Insurance = BestRX | AY2: Actual $ Purchased (Kinray Unit Price × Packages Billed To Ins) | BJ2: Net(Profit/Loss)$ = Actual $ Paid(BestRx) − Actual $ Purchased(Kinray)
A3: NDC # | B3: Drug Name | C3: Package Size | D3: KINRAY | E3: Total Purchased | F3: Kinray_UPrice | G3: ALL_PBM_Q | H3: ADAP_Q | I3: ARG/HUM_Q | J3: CVS_Q | K3: ESI_Q | L3: FDS_Q | M3: MEDIMP_Q | N3: NYM_Q | O3: OPTUM_Q | P3: PRIMECAPRX_Q | Q3: TREDIUM_Q | R3: ALL_PBM_P | S3: ADAP_P | T3: ARG/HUM_P | U3: CVS_P | V3: ESI_P | W3: FDS_P | X3: MEDIMP_P | Y3: NYM_P | Z3: OPTUM_P | AA3: PRIMECAPRX_P | AB3: TREDIUM_P | AC3: ALL_PBM_D | AD3: ADAP_D | AE3: ARG/HUM_D | AF3: CVS_D | AG3: ESI_D | AH3: FDS_D | AI3: MEDIMP_D | AJ3: NYM_D | AK3: OPTUM_D | AL3: PRIMECAPRX_D | AM3: TREDIUM_D | AN3: ALL_PBM_T | AO3: ADAP_T | AP3: ARG/HUM_T | AQ3: CVS_T | AR3: ESI_T | AS3: FDS_T | AT3: MEDIMP_T | AU3: NYM_T | AV3: OPTUM_T | AW3: PRIMECAPRX_T | AX3: TREDIUM_T | AY3: ALL_PBM_Pur | AZ3: ADAP_Pur | BA3: ARG/HUM_Pur | BB3: CVS_Pur | BC3: ESI_Pur | BD3: FDS_Pur | BE3: MEDIMP_Pur | BF3: NYM_Pur | BG3: OPTUM_Pur | BH3: PRIMECAPRX_Pur | BI3: TREDIUM_Pur | BJ3: ALL_PBM_Net | BK3: ADAP_Net | BL3: ARG/HUM_Net | BM3: CVS_Net | BN3: ESI_Net | BO3: FDS_Net | BP3: MEDIMP_Net | BQ3: NYM_Net | BR3: OPTUM_Net | BS3: PRIMECAPRX_Net | BT3: TREDIUM_Net
A4: 70000035801 | B4: A&D EXTERNAL OINTMENT | C4: 425 | D4: 0 | E4: 0 | F4: 0 | G4: 0 | H4: 0 | I4: 0 | J4: 0 | K4: 0 | L4: 0 | M4: 0 | N4: 425 | O4: 0 | P4: 0 | Q4: 0 | R4: 0 | S4: 0 | T4: 0 | U4: 0 | V4: 0 | W4: 0 | X4: 0 | Y4: 1 | Z4: 0 | AA4: 0 | AB4: 0 | AC4: 0 | AD4: 0 | AE4: 0 | AF4: 0 | AG4: 0 | AH4: 0 | AI4: 0 | AJ4: -1 | AK4: 0 | AL4: 0 | AM4: 0 | AN4: 0 | AO4: 0 | AP4: 0 | AQ4: 0 | AR4: 0 | AS4: 0 | AT4: 0 | AU4: 12 | AV4: 0 | AW4: 0 | AX4: 0 | AY4: 0 | AZ4: 0 | BA4: 0 | BB4: 0 | BC4: 0 | BD4: 0 | BE4: 0 | BF4: 0 | BG4: 0 | BH4: 0 | BI4: 0 | BJ4: 0 | BK4: 0 | BL4: 0 | BM4: 0 | BN4: 0 | BO4: 0 | BP4: 0 | BQ4: 12 | BR4: 0 | BS4: 0 | BT4: 0 | BU4: Unclassified
A5: 59148000713 | B5: ABILIFY 5MG TABLET | C5: 30 | D5: 1 | E5: 1 | F5: 568 | G5: 30 | H5: 0 | I5: 0 | J5: 0 | K5: 0 | L5: 0 | M5: 0 | N5: 30 | O5: 0 | P5: 0 | Q5: 0 | R5: 1 | S5: 0 | T5: 0 | U5: 0 | V5: 0 | W5: 0 | X5: 0 | Y5: 1 | Z5: 0 | AA5: 0 | AB5: 0 | AC5: 0 | AD5: 1 | AE5: 1 | AF5: 1 | AG5: 1 | AH5: 1 | AI5: 1 | AJ5: 0 | AK5: 1 | AL5: 1 | AM5: 1 | AN5: 571 | AO5: 0 | AP5: 0 | AQ5: 0 | AR5: 0 | AS5: 0 | AT5: 0 | AU5: 571 | AV5: 0 | AW5: 0 | AX5: 0 | AY5: 568 | AZ5: 0 | BA5: 0 | BB5: 0 | BC5: 0 | BD5: 0 | BE5: 0 | BF5: 568 | BG5: 0 | BH5: 0 | BI5: 0 | BJ5: 3 | BK5: 0 | BL5: 0 | BM5: 0 | BN5: 0 | BO5: 0 | BP5: 0 | BQ5: 3 | BR5: 0 | BS5: 0 | BT5: 0 | BU5: Branded Drug
A6: 65702071110 | B6: ACCU-CHEK GUIDE IN VITRO STRIP | C6: 50 | D6: 16 | E6: 16 | F6: 20 | G6: 900 | H6: 0 | I6: 200 | J6: 200 | K6: 500 | L6: 0 | M6: 0 | N6: 0 | O6: 0 | P6: 0 | Q6: 0 | R6: 18 | S6: 0 | T6: 4 | U6: 4 | V6: 10 | W6: 0 | X6: 0 | Y6: 0 | Z6: 0 | AA6: 0 | AB6: 0 | AC6: -2 | AD6: 16 | AE6: 12 | AF6: 12 | AG6: 6 | AH6: 16 | AI6: 16 | AJ6: 16 | AK6: 16 | AL6: 16 | AM6: 16 | AN6: 332 | AO6: 0 | AP6: 68 | AQ6: 78 | AR6: 164 | AS6: 0 | AT6: 0 | AU6: 0 | AV6: 0 | AW6: 0 | AX6: 0 | AY6: 360 | AZ6: 0 | BA6: 80 | BB6: 80 | BC6: 200 | BD6: 0 | BE6: 0 | BF6: 0 | BG6: 0 | BH6: 0 | BI6: 0 | BJ6: -28 | BK6: 0 | BL6: -12 | BM6: -2 | BN6: -36 | BO6: 0 | BP6: 0 | BQ6: 0 | BR6: 0 | BS6: 0 | BT6: 0 | BU6: Home Health Care
A7: 65702072910 | B7: ACCU-CHEK GUIDE W/DEVICE KIT | C7: 1 | D7: 3 | E7: 3 | F7: 26 | G7: 1 | H7: 0 | I7: 0 | J7: 0 | K7: 1 | L7: 0 | M7: 0 | N7: 0 | O7: 0 | P7: 0 | Q7: 0 | R7: 1 | S7: 0 | T7: 0 | U7: 0 | V7: 1 | W7: 0 | X7: 0 | Y7: 0 | Z7: 0 | AA7: 0 | AB7: 0 | AC7: 2 | AD7: 3 | AE7: 3 | AF7: 3 | AG7: 2 | AH7: 3 | AI7: 3 | AJ7: 3 | AK7: 3 | AL7: 3 | AM7: 3 | AN7: 21 | AO7: 0 | AP7: 0 | AQ7: 0 | AR7: 21 | AS7: 0 | AT7: 0 | AU7: 0 | AV7: 0 | AW7: 0 | AX7: 0 | AY7: 26 | AZ7: 0 | BA7: 0 | BB7: 0 | BC7: 26 | BD7: 0 | BE7: 0 | BF7: 0 | BG7: 0 | BH7: 0 | BI7: 0 | BJ7: -5 | BK7: 0 | BL7: 0 | BM7: 0 | BN7: -5 | BO7: 0 | BP7: 0 | BQ7: 0 | BR7: 0 | BS7: 0 | BT7: 0 | BU7: Home Health Care
A8: 50924097110 | B8: ACCU-CHEK SOFTCLIX LANCETS | C8: 100 | D8: 0 | E8: 0 | F8: 0 | G8: 0 | H8: 0 | I8: 0 | J8: 300 | K8: 0 | L8: 0 | M8: 0 | N8: 0 | O8: 0 | P8: 0 | Q8: 0 | R8: 0 | S8: 0 | T8: 0 | U8: 3 | V8: 0 | W8: 0 | X8: 0 | Y8: 0 | Z8: 0 | AA8: 0 | AB8: 0 | AC8: 0 | AD8: 0 | AE8: 0 | AF8: -3 | AG8: 0 | AH8: 0 | AI8: 0 | AJ8: 0 | AK8: 0 | AL8: 0 | AM8: 0 | AN8: 0 | AO8: 0 | AP8: 0 | AQ8: 31 | AR8: 0 | AS8: 0 | AT8: 0 | AU8: 0 | AV8: 0 | AW8: 0 | AX8: 0 | AY8: 0 | AZ8: 0 | BA8: 0 | BB8: 0 | BC8: 0 | BD8: 0 | BE8: 0 | BF8: 0 | BG8: 0 | BH8: 0 | BI8: 0 | BJ8: 0 | BK8: 0 | BL8: 0 | BM8: 31 | BN8: 0 | BO8: 0 | BP8: 0 | BQ8: 0 | BR8: 0 | BS8: 0 | BT8: 0 | BU8: Unclassified
A9: 45802073230 | B9: ACETAMINOPHEN 120 MG RECTAL SUPPOSITORY | C9: 12 | D9: 0 | E9: 0 | F9: 0 | G9: 0 | H9: 0 | I9: 0 | J9: 0 | K9: 0 | L9: 0 | M9: 0 | N9: 12 | O9: 0 | P9: 0 | Q9: 0 | R9: 0 | S9: 0 | T9: 0 | U9: 0 | V9: 0 | W9: 0 | X9: 0 | Y9: 1 | Z9: 0 | AA9: 0 | AB9: 0 | AC9: 0 | AD9: 0 | AE9: 0 | AF9: 0 | AG9: 0 | AH9: 0 | AI9: 0 | AJ9: -1 | AK9: 0 | AL9: 0 | AM9: 0 | AN9: 0 | AO9: 0 | AP9: 0 | AQ9: 0 | AR9: 0 | AS9: 0 | AT9: 0 | AU9: 12 | AV9: 0 | AW9: 0 | AX9: 0 | AY9: 0 | AZ9: 0 | BA9: 0 | BB9: 0 | BC9: 0 | BD9: 0 | BE9: 0 | BF9: 0 | BG9: 0 | BH9: 0 | BI9: 0 | BJ9: 0 | BK9: 0 | BL9: 0 | BM9: 0 | BN9: 0 | BO9: 0 | BP9: 0 | BQ9: 12 | BR9: 0 | BS9: 0 | BT9: 0 | BU9: Unclassified
A10: 57237030412 | B10: ACETAMINOPHEN 160 MG/5ML ORAL SOLUTION | C10: 118 | D10: 10 | E10: 10 | F10: 3 | G10: 0 | H10: 0 | I10: 0 | J10: 0 | K10: 0 | L10: 0 | M10: 0 | N10: 354 | O10: 0 | P10: 0 | Q10: 0 | R10: 0 | S10: 0 | T10: 0 | U10: 0 | V10: 0 | W10: 0 | X10: 0 | Y10: 3 | Z10: 0 | AA10: 0 | AB10: 0 | AC10: 10 | AD10: 10 | AE10: 10 | AF10: 10 | AG10: 10 | AH10: 10 | AI10: 10 | AJ10: 7 | AK10: 10 | AL10: 10 | AM10: 10 | AN10: 0 | AO10: 0 | AP10: 0 | AQ10: 0 | AR10: 0 | AS10: 0 | AT10: 0 | AU10: 14 | AV10: 0 | AW10: 0 | AX10: 0 | AY10: 0 | AZ10: 0 | BA10: 0 | BB10: 0 | BC10: 0 | BD10: 0 | BE10: 0 | BF10: 9 | BG10: 0 | BH10: 0 | BI10: 0 | BJ10: 0 | BK10: 0 | BL10: 0 | BM10: 0 | BN10: 0 | BO10: 0 | BP10: 0 | BQ10: 5 | BR10: 0 | BS10: 0 | BT10: 0 | BU10: OTC Drug
A11: 00536132701 | B11: ACETAMINOPHEN 325 MG TABLET * TYLENOL REGULAR | C11: 100 | D11: 0 | E11: 0 | F11: 0 | G11: 0 | H11: 0 | I11: 0 | J11: 0 | K11: 0 | L11: 0 | M11: 0 | N11: 160 | O11: 0 | P11: 0 | Q11: 0 | R11: 0 | S11: 0 | T11: 0 | U11: 0 | V11: 0 | W11: 0 | X11: 0 | Y11: 1.6 | Z11: 0 | AA11: 0 | AB11: 0 | AC11: 0 | AD11: 0 | AE11: 0 | AF11: 0 | AG11: 0 | AH11: 0 | AI11: 0 | AJ11: -1.6 | AK11: 0 | AL11: 0 | AM11: 0 | AN11: 0 | AO11: 0 | AP11: 0 | AQ11: 0 | AR11: 0 | AS11: 0 | AT11: 0 | AU11: 33 | AV11: 0 | AW11: 0 | AX11: 0 | AY11: 0 | AZ11: 0 | BA11: 0 | BB11: 0 | BC11: 0 | BD11: 0 | BE11: 0 | BF11: 0 | BG11: 0 | BH11: 0 | BI11: 0 | BJ11: 0 | BK11: 0 | BL11: 0 | BM11: 0 | BN11: 0 | BO11: 0 | BP11: 0 | BQ11: 33 | BR11: 0 | BS11: 0 | BT11: 0 | BU11: Unclassified
A12: 00536132710 | B12: ACETAMINOPHEN 325MG TABLET | C12: 1000 | D12: 0 | E12: 0 | F12: 0 | G12: 0 | H12: 0 | I12: 0 | J12: 120 | K12: 0 | L12: 0 | M12: 0 | N12: 578 | O12: 0 | P12: 0 | Q12: 0 | R12: 0 | S12: 0 | T12: 0 | U12: 0.12 | V12: 0 | W12: 0 | X12: 0 | Y12: 0.578 | Z12: 0 | AA12: 0 | AB12: 0 | AC12: 0 | AD12: 0 | AE12: 0 | AF12: -0.12 | AG12: 0 | AH12: 0 | AI12: 0 | AJ12: -0.578 | AK12: 0 | AL12: 0 | AM12: 0 | AN12: 0 | AO12: 0 | AP12: 0 | AQ12: 1 | AR12: 0 | AS12: 0 | AT12: 0 | AU12: 79 | AV12: 0 | AW12: 0 | AX12: 0 | AY12: 0 | AZ12: 0 | BA12: 0 | BB12: 0 | BC12: 0 | BD12: 0 | BE12: 0 | BF12: 0 | BG12: 0 | BH12: 0 | BI12: 0 | BJ12: 0 | BK12: 0 | BL12: 0 | BM12: 1 | BN12: 0 | BO12: 0 | BP12: 0 | BQ12: 79 | BR12: 0 | BS12: 0 | BT12: 0 | BU12: Unclassified
A13: 00904672080 | B13: ACETAMINOPHEN 500MG TABLET NYM | C13: 1000 | D13: 0 | E13: 0 | F13: 0 | G13: 0 | H13: 0 | I13: 0 | J13: 0 | K13: 0 | L13: 0 | M13: 0 | N13: 1694 | O13: 0 | P13: 0 | Q13: 0 | R13: 0 | S13: 0 | T13: 0 | U13: 0 | V13: 0 | W13: 0 | X13: 0 | Y13: 1.694 | Z13: 0 | AA13: 0 | AB13: 0 | AC13: 0 | AD13: 0 | AE13: 0 | AF13: 0 | AG13: 0 | AH13: 0 | AI13: 0 | AJ13: -1.694 | AK13: 0 | AL13: 0 | AM13: 0 | AN13: 0 | AO13: 0 | AP13: 0 | AQ13: 0 | AR13: 0 | AS13: 0 | AT13: 0 | AU13: 227 | AV13: 0 | AW13: 0 | AX13: 0 | AY13: 0 | AZ13: 0 | BA13: 0 | BB13: 0 | BC13: 0 | BD13: 0 | BE13: 0 | BF13: 0 | BG13: 0 | BH13: 0 | BI13: 0 | BJ13: 0 | BK13: 0 | BL13: 0 | BM13: 0 | BN13: 0 | BO13: 0 | BP13: 0 | BQ13: 227 | BR13: 0 | BS13: 0 | BT13: 0 | BU13: Unclassified
A14: 00904701420 | B14: ACETAMINOPHEN CHILDRENS 160 MG/5ML ORAL SOLUTION | C14: 118 | D14: 0 | E14: 0 | F14: 0 | G14: 0 | H14: 0 | I14: 0 | J14: 236 | K14: 0 | L14: 0 | M14: 0 | N14: 1180 | O14: 0 | P14: 0 | Q14: 0 | R14: 0 | S14: 0 | T14: 0 | U14: 2 | V14: 0 | W14: 0 | X14: 0 | Y14: 10 | Z14: 0 | AA14: 0 | AB14: 0 | AC14: 0 | AD14: 0 | AE14: 0 | AF14: -2 | AG14: 0 | AH14: 0 | AI14: 0 | AJ14: -10 | AK14: 0 | AL14: 0 | AM14: 0 | AN14: 0 | AO14: 0 | AP14: 0 | AQ14: 1 | AR14: 0 | AS14: 0 | AT14: 0 | AU14: 63 | AV14: 0 | AW14: 0 | AX14: 0 | AY14: 0 | AZ14: 0 | BA14: 0 | BB14: 0 | BC14: 0 | BD14: 0 | BE14: 0 | BF14: 0 | BG14: 0 | BH14: 0 | BI14: 0 | BJ14: 0 | BK14: 0 | BL14: 0 | BM14: 1 | BN14: 0 | BO14: 0 | BP14: 0 | BQ14: 63 | BR14: 0 | BS14: 0 | BT14: 0 | BU14: Unclassified
A15: 45802020126 | B15: ACETAMINOPHEN CHILDRENS 160 MG/5ML ORAL SUSPENSION | C15: 118 | D15: 3 | E15: 3 | F15: 3 | G15: 0 | H15: 0 | I15: 0 | J15: 0 | K15: 0 | L15: 0 | M15: 0 | N15: 118 | O15: 0 | P15: 0 | Q15: 0 | R15: 0 | S15: 0 | T15: 0 | U15: 0 | V15: 0 | W15: 0 | X15: 0 | Y15: 1 | Z15: 0 | AA15: 0 | AB15: 0 | AC15: 3 | AD15: 3 | AE15: 3 | AF15: 3 | AG15: 3 | AH15: 3 | AI15: 3 | AJ15: 2 | AK15: 3 | AL15: 3 | AM15: 3 | AN15: 0 | AO15: 0 | AP15: 0 | AQ15: 0 | AR15: 0 | AS15: 0 | AT15: 0 | AU15: 11 | AV15: 0 | AW15: 0 | AX15: 0 | AY15: 0 | AZ15: 0 | BA15: 0 | BB15: 0 | BC15: 0 | BD15: 0 | BE15: 0 | BF15: 3 | BG15: 0 | BH15: 0 | BI15: 0 | BJ15: 0 | BK15: 0 | BL15: 0 | BM15: 0 | BN15: 0 | BO15: 0 | BP15: 0 | BQ15: 8 | BR15: 0 | BS15: 0 | BT15: 0 | BU15: OTC Drug
... A906: 69557011130 | B906: ZTLIDO 1.8 % EXTERNAL PATCH | C906: 30 | D906: 0 | E906: 0 | F906: 0 | G906: 60 | H906: 0 | I906: 0 | J906: 60 | K906: 0 | L906: 0 | M906: 0 | N906: 0 | O906: 0 | P906: 0 | Q906: 0 | R906: 2 | S906: 0 | T906: 0 | U906: 2 | V906: 0 | W906: 0 | X906: 0 | Y906: 0 | Z906: 0 | AA906: 0 | AB906: 0 | AC906: -2 | AD906: 0 | AE906: 0 | AF906: -2 | AG906: 0 | AH906: 0 | AI906: 0 | AJ906: 0 | AK906: 0 | AL906: 0 | AM906: 0 | AN906: 721 | AO906: 0 | AP906: 0 | AQ906: 715 | AR906: 0 | AS906: 0 | AT906: 0 | AU906: 0 | AV906: 0 | AW906: 0 | AX906: 0 | AY906: 0 | AZ906: 0 | BA906: 0 | BB906: 0 | BC906: 0 | BD906: 0 | BE906: 0 | BF906: 0 | BG906: 0 | BH906: 0 | BI906: 0 | BJ906: 721 | BK906: 0 | BL906: 0 | BM906: 715 | BN906: 0 | BO906: 0 | BP906: 0 | BQ906: 0 | BR906: 0 | BS906: 0 | BT906: 0 | BU906: Unclassified
A907: Totals | AN907: =SUM(AN4:AN906) | AO907: =SUM(AO4:AO906) | AP907: =SUM(AP4:AP906) | AQ907: =SUM(AQ4:AQ906) | AR907: =SUM(AR4:AR906) | AS907: =SUM(AS4:AS906) | AT907: =SUM(AT4:AT906) | AU907: =SUM(AU4:AU906) | ... BT907: =SUM(BT4:BT906)

Sheet BIN to Processor
A1: BIN Numbers Billed (from Custom Log) | F1: Unmapped BIN Numbers (000000)
A2: BIN | B2: Processor | C2: Total Rx | F2: BIN | G2: RX # | H2: Fill Date
A3: 610490 | B3: ADAP | C3: 2 | F3: 000000 | G3: 109042 | H3: 2026-02-02
A4: 015581 | B4: ARG/HUM | C4: 6 | F4: 000000 | G4: 109043 | H4: 2026-02-02
A5: 015599 | B5: ARG/HUM | C5: 6 | F5: 000000 | G5: 109044 | H5: 2026-02-02
A6: 004336 | B6: CVS | C6: 1724 | F6: 000000 | G6: 141403 | H6: 2026-02-02
A7: 020099 | B7: CVS | C7: 11 | F7: 000000 | G7: 141413 | H7: 2026-02-02
A8: 020107 | B8: CVS | C8: 14 | F8: 000000 | G8: 141416 | H8: 2026-02-02
A9: 020115 | B9: CVS | C9: 14 | F9: 000000 | G9: 141417 | H9: 2026-02-02
A10: 610239 | B10: CVS | C10: 5 | F10: 000000 | G10: 141457 | H10: 2026-02-02
A11: 610502 | B11: CVS | C11: 51 | F11: 000000 | G11: 141458 | H11: 2026-02-02
A12: 003858 | B12: ESI | C12: 80 | F12: 000000 | G12: 141462 | H12: 2026-02-02
A13: 017010 | B13: ESI | C13: 41 | F13: 000000 | G13: 141463 | H13: 2026-02-02
A14: 610014 | B14: ESI | C14: 196 | F14: 000000 | G14: 141464 | H14: 2026-02-02
... A28: 000000 | B28: Unmapped | C28: 302 | F28: 000000 | G28: 141918 | H28: 2026-02-04
B29: Grand Total | C29: =SUM(C3:C28) | F29: 000000 | G29: 141944 | H29: 2026-02-04
F30: 000000 | G30: 131064 | H30: 2026-02-05
F31: 000000 | G31: 131066 | H31: 2026-02-05
F32: 000000 | G32: 131067 | H32: 2026-02-05
F33: 000000 | G33: 142022 | H33: 2026-02-05
F34: 000000 | G34: 142023 | H34: 2026-02-05
F35: 000000 | G35: 142030 | H35: 2026-02-05
F36: 000000 | G36: 142031 | H36: 2026-02-05
F37: 000000 | G37: 142032 | H37: 2026-02-05
F38: 000000 | G38: 142074 | H38: 2026-02-05
F39: 000000 | G39: 142075 | H39: 2026-02-05
F40: 000000 | G40: 142076 | H40: 2026-02-05
F41: 000000 | G41: 142091 | H41: 2026-02-05
... F304: 000000 | G304: 145316 | H304: 2026-02-28

Sheet Needs to be ordered - All
A1: Trial 20 (Feb 2026 - Feb 2026) - Need to Order - ALL
A2: NDC # | B2: Drug Name | C2: Pkg Size | D2: ADAP_D | E2: ARG/HUM_D | F2: CVS_D | G2: ESI_D | H2: FDS_D | I2: MEDIMP_D | J2: NYM_D | K2: OPTUM_D | L2: PRIMECAPRX_D | M2: TREDIUM_D | N2: To Order | O2: Paper Work | P2: PRICE | Q2: Total Order Price | R2: Insurance-wise Order Estimate ($) | S2: Amount
A3: 70000035801 | B3: A&D EXTERNAL OINTMENT | C3: 425 | D3: 0 | E3: 0 | F3: 0 | G3: 0 | H3: 0 | I3: 0 | J3: -1 | K3: 0 | L3: 0 | M3: 0 | N3: 1 | P3: 0 | Q3: 0 | R3: ADAP_D | S3: =SUMPRODUCT((-D3:D676)*(D3:D676<0),P3:P676)
A4: 50924097110 | B4: ACCU-CHEK SOFTCLIX LANCETS | C4: 100 | D4: 0 | E4: 0 | F4: -3 | G4: 0 | H4: 0 | I4: 0 | J4: 0 | K4: 0 | L4: 0 | M4: 0 | N4: 3 | P4: 0 | Q4: 0 | R4: ARG/HUM_D | S4: =SUMPRODUCT((-E3:E676)*(E3:E676<0),P3:P676)
A5: 45802073230 | B5: ACETAMINOPHEN 120 MG RECTAL SUPPOSITORY | C5: 12 | D5: 0 | E5: 0 | F5: 0 | G5: 0 | H5: 0 | I5: 0 | J5: -1 | K5: 0 | L5: 0 | M5: 0 | N5: 1 | P5: 0 | Q5: 0 | R5: CVS_D | S5: =SUMPRODUCT((-F3:F676)*(F3:F676<0),P3:P676)
A6: 00536132701 | B6: ACETAMINOPHEN 325 MG TABLET * TYLENOL REGULAR | C6: 100 | D6: 0 | E6: 0 | F6: 0 | G6: 0 | H6: 0 | I6: 0 | J6: -1.6 | K6: 0 | L6: 0 | M6: 0 | N6: 1.6 | P6: 0 | Q6: 0 | R6: ESI_D | S6: =SUMPRODUCT((-G3:G676)*(G3:G676<0),P3:P676)
A7: 00536132710 | B7: ACETAMINOPHEN 325MG TABLET | C7: 1000 | D7: 0 | E7: 0 | F7: -0.12 | G7: 0 | H7: 0 | I7: 0 | J7: -0.58 | K7: 0 | L7: 0 | M7: 0 | N7: 0.58 | P7: 0 | Q7: 0 | R7: FDS_D | S7: =SUMPRODUCT((-H3:H676)*(H3:H676<0),P3:P676)
A8: 00904672080 | B8: ACETAMINOPHEN 500MG TABLET NYM | C8: 1000 | D8: 0 | E8: 0 | F8: 0 | G8: 0 | H8: 0 | I8: 0 | J8: -1.69 | K8: 0 | L8: 0 | M8: 0 | N8: 1.69 | P8: 0 | Q8: 0 | R8: MEDIMP_D | S8: =SUMPRODUCT((-I3:I676)*(I3:I676<0),P3:P676)
A9: 00904701420 | B9: ACETAMINOPHEN CHILDRENS 160 MG/5ML ORAL SOLUTION | C9: 118 | D9: 0 | E9: 0 | F9: -2 | G9: 0 | H9: 0 | I9: 0 | J9: -10 | K9: 0 | L9: 0 | M9: 0 | N9: 10 | P9: 0 | Q9: 0 | R9: NYM_D | S9: =SUMPRODUCT((-J3:J676)*(J3:J676<0),P3:P676)
A10: 00904672040 | B10: ACETAMINOPHEN EXTRA STRENGTH 500MG TABLET **** NYM | C10: 500 | D10: 0 | E10: 0 | F10: 0 | G10: 0 | H10: 0 | I10: 0 | J10: -3 | K10: 0 | L10: 0 | M10: 0 | N10: 3 | P10: 0 | Q10: 0 | R10: OPTUM_D | S10: =SUMPRODUCT((-K3:K676)*(K3:K676<0),P3:P676)
A11: 72578015001 | B11: ACETAZOLAMIDE 250 MG ORAL TABLET | C11: 100 | D11: 0 | E11: 0 | F11: -1.8 | G11: 0 | H11: 0 | I11: 0 | J11: 0 | K11: 0 | L11: 0 | M11: 0 | N11: 1.8 | P11: 0 | Q11: 0 | R11: PRIMECAPRX_D | S11: =SUMPRODUCT((-L3:L676)*(L3:L676<0),P3:P676)
A12: 72578000205 | B12: ACYCLOVIR 200MG CAPSULE | C12: 500 | D12: 0 | E12: 0 | F12: -0.18 | G12: 0 | H12: 0 | I12: 0 | J12: 0 | K12: 0 | L12: 0 | M12: 0 | N12: 0.18 | P12: 0 | Q12: 0 | R12: TREDIUM_D | S12: =SUMPRODUCT((-M3:M676)*(M3:M676<0),P3:P676)
A13: 68462074635 | B13: ACYCLOVIR 5 % EXTERNAL OINTMENT | C13: 30 | D13: 0 | E13: 0 | F13: -1 | G13: 0 | H13: 0 | I13: 0 | J13: 0 | K13: 0 | L13: 0 | M13: 0 | N13: 1 | P13: 0 | Q13: 0 | R13: Unclassified
A14: 31722077801 | B14: ACYCLOVIR 800 MG TABLET | C14: 100 | D14: 0 | E14: 0 | F14: 0 | G14: 0 | H14: 0 | I14: 0 | J14: -0.2 | K14: 0 | L14: 0 | M14: 0 | N14: 0.2 | P14: 0 | Q14: 0 | R14: Unclassified
A15: 47335070352 | B15: ALBUTEROL SULFATE (2.5 MG/3ML) 0.083% INHALATION NEBULIZATION SOLUTION | C15: 90 | D15: 0 | E15: 0 | F15: -1 | G15: 0 | H15: 0 | I15: 0 | J15: -1 | K15: 0 | L15: 0 | M15: 0 | N15: 1 | P15: 0 | Q15: 0 | R15: Unclassified
A16: 76204020030 | B16: ALBUTEROL SULFATE (2.5 MG/3ML) 0.083% INHALATION NEBULIZATION SOLUTION | C16: 90 | D16: 0 | E16: 0 | F16: -3 | G16: -2 | H16: 0 | I16: 0 | J16: -3 | K16: 0 | L16: 0 | M16: 0 | N16: 3 | P16: 0 | Q16: 0 | R16: Unclassified
A17: 00378705752 | B17: ALBUTEROL SULFATE 0.63 MG/3ML INHALATION NEBULIZATION SOLUTION | C17: 75 | D17: 0 | E17: 0 | F17: -2 | G17: 0 | H17: 0 | I17: 0 | J17: -1 | K17: 0 | L17: 0 | M17: 0 | N17: 2 | P17: 0 | Q17: 0 | R17: Unclassified
A18: 91237000128 | B18: ALCOHOL PADS EASY COMFORT ALPINE | C18: 100 | D18: 0 | E18: 0 | F18: 0 | G18: -3 | H18: 0 | I18: -2 | J18: -1 | K18: 0 | L18: 0 | M18: 0 | N18: 3 | P18: 0 | Q18: 0 | R18: Unclassified
A19: 08222440006 | B19: ALCOHOL PADS ULTICARE | C19: 100 | D19: 0 | E19: 0 | F19: -14 | G19: -1 | H19: 0 | I19: 0 | J19: -3 | K19: -2 | L19: 0 | M19: 0 | N19: 14 | P19: 0 | Q19: 0 | R19: Unclassified
A20: 00536110301 | B20: ALCOHOL PREP 70 % PAD CVS | C20: 100 | D20: 0 | E20: 0 | F20: -11 | G20: 0 | H20: 0 | I20: 0 | J20: 0 | K20: 0 | L20: 0 | M20: 0 | N20: 11 | P20: 0 | Q20: 0 | R20: Unclassified
A21: 69097022416 | B21: ALENDRONATE 70MG TAB | C21: 4 | D21: 10 | E21: 10 | F21: -11 | G21: 5 | H21: 10 | I21: 10 | J21: 10 | K21: 9 | L21: 10 | M21: 10 | N21: 11 | P21: 1 | Q21: 11 | R21: Generic Drug
A22: 10135069712 | B22: ALENDRONATE 70MG TABLET | C22: 12 | D22: 0 | E22: 0 | F22: -1 | G22: 0 | H22: 0 | I22: 0 | J22: 0 | K22: 0 | L22: 0 | M22: 0 | N22: 1 | P22: 0 | Q22: 0 | R22: Unclassified
A23: 64980034001 | B23: ALENDRONATE SODIUM 10 MG ORAL TABLET | C23: 100 | D23: 0 | E23: 0 | F23: -0.28 | G23: 0 | H23: 0 | I23: 0 | J23: 0 | K23: 0 | L23: 0 | M23: 0 | N23: 0.28 | P23: 0 | Q23: 0 | R23: Unclassified
A24: 29300015501 | B24: ALFUZOSIN HCL ER 10 MG TABLET | C24: 100 | D24: 0 | E24: 0 | F24: -0.91 | G24: 0 | H24: 0 | I24: 0 | J24: 0 | K24: 0 | L24: 0 | M24: 0 | N24: 0.91 | P24: 0 | Q24: 0 | R24: Unclassified
... A676: 69557011130 | B676: ZTLIDO 1.8 % EXTERNAL PATCH | C676: 30 | D676: 0 | E676: 0 | F676: -2 | G676: 0 | H676: 0 | I676: 0 | J676: 0 | K676: 0 | L676: 0 | M676: 0 | N676: 2 | P676: 0 | Q676: 0 | R676: Unclassified
P678: Grand Total | Q678: =SUBTOTAL(109,Q3:Q676)

Sheet Do Not Order - ALL
A1: Trial 20 (Feb 2026 - Feb 2026) - Do Not Order
A2: NDC # | B2: Drug Name | C2: Pkg Size | D2: ADAP_D | E2: ARG/HUM_D | F2: CVS_D | G2: ESI_D | H2: FDS_D | I2: MEDIMP_D | J2: NYM_D | K2: OPTUM_D | L2: PRIMECAPRX_D | M2: TREDIUM_D | N2: Do Not Order | O2: Paper Work | P2: Drug Type
A3: 65702071110 | B3: ACCU-CHEK GUIDE IN VITRO STRIP | C3: 50 | D3: 16 | E3: 12 | F3: 12 | G3: 6 | H3: 16 | I3: 16 | J3: 16 | K3: 16 | L3: 16 | M3: 16 | N3: 6 | P3: Home Health Care
A4: 65702072910 | B4: ACCU-CHEK GUIDE W/DEVICE KIT | C4: 1 | D4: 3 | E4: 3 | F4: 3 | G4: 2 | H4: 3 | I4: 3 | J4: 3 | K4: 3 | L4: 3 | M4: 3 | N4: 2 | P4: Home Health Care
A5: 57237030412 | B5: ACETAMINOPHEN 160 MG/5ML ORAL SOLUTION | C5: 118 | D5: 10 | E5: 10 | F5: 10 | G5: 10 | H5: 10 | I5: 10 | J5: 7 | K5: 10 | L5: 10 | M5: 10 | N5: 7 | P5: OTC Drug
A6: 45802020126 | B6: ACETAMINOPHEN CHILDRENS 160 MG/5ML ORAL SUSPENSION | C6: 118 | D6: 3 | E6: 3 | F6: 3 | G6: 3 | H6: 3 | I6: 3 | J6: 2 | K6: 3 | L6: 3 | M6: 3 | N6: 2 | P6: OTC Drug
A7: 00904731427 | B7: ACETAMINOPHEN ER 650MG TABLET ER | C7: 400 | D7: 2 | E7: 2 | F7: 1.55 | G7: 2 | H7: 2 | I7: 2 | J7: 0.63 | K7: 2 | L7: 2 | M7: 2 | N7: 0.63 | P7: OTC Drug
A8: 00904673080 | B8: ACETAMINOPHEN EXTRA STRENGTH 500 MG ORAL TABLET | C8: 1000 | D8: 5 | E8: 5 | F8: 5 | G8: 5 | H8: 5 | I8: 5 | J8: 4.68 | K8: 5 | L8: 5 | M8: 5 | N8: 4.68 | P8: OTC Drug
A9: 00173071720 | B9: ADVAIR HFA 230-21 MCG/ACT INHALATION AEROSOL | C9: 12 | D9: 2 | E9: 2 | F9: 2 | G9: 2 | H9: 2 | I9: 2 | J9: 1 | K9: 2 | L9: 2 | M9: 2 | N9: 1 | P9: Branded Drug
A10: 00310908012 | B10: AIRSUPRA 90-80 MCG/ACT INHALATION AEROSOL | C10: 10.7 | D10: 3 | E10: 3 | F10: 2 | G10: 2 | H10: 3 | I10: 3 | J10: 2 | K10: 3 | L10: 3 | M10: 3 | N10: 2 | P10: Branded Drug
A11: 66993001968 | B11: ALBUTEROL HFA 108 MCG/AC (VENTOLIN 18GM) | C11: 18 | D11: 24 | E11: 24 | F11: 1 | G11: 24 | H11: 24 | I11: 20 | J11: 24 | K11: 24 | L11: 24 | M11: 24 | N11: 1 | P11: Generic Drug
A12: 68180096301 | B12: ALBUTEROL SULFATE HFA 108 (90 BASE)MCG/ACT AEROSOL | C12: 8.5 | D12: 48 | E12: 47 | F12: 14 | G12: 38 | H12: 48 | I12: 44 | J12: 8 | K12: 42 | L12: 48 | M12: 48 | N12: 8 | P12: Generic Drug
A13: 65862067901 | B13: ALPRAZOLAM 2 MG ORAL TABLET | C13: 100 | D13: 3 | E13: 3 | F13: 3 | G13: 3 | H13: 3 | I13: 3 | J13: 2.1 | K13: 3 | L13: 3 | M13: 3 | N13: 2.1 | P13: Generic Drug
A14: 67877019710 | B14: AMLODIPINE 2.5MG TABLET | C14: 1000 | D14: 1 | E14: 1 | F14: 0.55 | G14: 1 | H14: 1 | I14: 1 | J14: 0.79 | K14: 1 | L14: 1 | M14: 1 | N14: 0.55 | P14: Generic Drug
... A171: 00536131698 | B171: ZINC OXIDE 20 % EXTERNAL OINTMENT | C171: 454 | D171: 4 | E171: 4 | F171: 4 | G171: 4 | H171: 4 | I171: 4 | J171: 1 | K171: 4 | L171: 4 | M171: 4 | N171: 1 | P171: OTC Drug

Sheet Never Ordered - Check
A1: Trial 20 (Feb 2026 - Feb 2026) - Never Ordered Package - Check
A2: Drug Name | B2: NDC # | C2: Pkg Size | D2: Total Purchased | E2: ALL_PBM_P
A3: ACETAZOLAMIDE 250 MG ORAL TABLET | B3: 72578015001 | C3: 100 | D3: 0 | E3: 1.8
A4: ACYCLOVIR 200MG CAPSULE | B4: 72578000205 | C4: 500 | D4: 0 | E4: 0.18
A5: ACYCLOVIR 5 % EXTERNAL OINTMENT | B5: 68462074635 | C5: 30 | D5: 0 | E5: 1
A6: ACYCLOVIR 800 MG TABLET | B6: 31722077801 | C6: 100 | D6: 0 | E6: 0.2
A7: ALBUTEROL SULFATE (2.5 MG/3ML) 0.083% INHALATION NEBULIZATION SOLUTION | B7: 47335070352 | C7: 90 | D7: 0 | E7: 2
A8: ALBUTEROL SULFATE (2.5 MG/3ML) 0.083% INHALATION NEBULIZATION SOLUTION | B8: 76204020030 | C8: 90 | D8: 0 | E8: 8
A9: ALBUTEROL SULFATE 0.63 MG/3ML INHALATION NEBULIZATION SOLUTION | B9: 00378705752 | C9: 75 | D9: 0 | E9: 3
A10: ALCOHOL PADS EASY COMFORT ALPINE | B10: 91237000128 | C10: 100 | D10: 0 | E10: 6
A11: ALCOHOL PADS ULTICARE | B11: 08222440006 | C11: 100 | D11: 0 | E11: 20
A12: ALENDRONATE 70MG TABLET | B12: 10135069712 | C12: 12 | D12: 0 | E12: 1
A13: ALENDRONATE SODIUM 10 MG ORAL TABLET | B13: 64980034001 | C13: 100 | D13: 0 | E13: 0.28
A14: ALFUZOSIN HCL ER 10 MG TABLET | B14: 29300015501 | C14: 100 | D14: 0 | E14: 0.91
... A560: ZTLIDO 1.8 % EXTERNAL PATCH | B560: 69557011130 | C560: 30 | D560: 0 | E560: 2

Sheet RX Comparison - All
A1: RX Comparision Analysis (All RXs)
A2: RX | B2: Fill Date | C2: NDC | D2: Drug Name | E2: Pkg Size | F2: Qty Filled | G2: Package Billed | H2: Kinray Final Price | I2: Ins Paid | J2: SDRA Amt | K2: COPAY | L2: Total = (Ins Paid + SDRA + COPAY) | M2: Difference | N2: BIN | O2: Processor | P2: PCN | Q2: Group
A3: 137902 | B3: 46057 | C3: 70000035801 | D3: A&D EXTERNAL OINTMENT | E3: 425 | F3: 425 | G3: 1 | H3: 0 | I3: 12.01 | J3: 0 | K3: 0 | L3: 12.01 | M3: 0 | N3: 004740 | O3: NYM | P3: 9314DA31
A4: 144533 | B4: 46077 | C4: 59148000713 | D4: ABILIFY 5MG TABLET | E4: 30 | F4: 30 | G4: 1 | H4: 568 | I4: 570.77 | J4: 0 | K4: 0 | L4: 570.77 | M4: 2.77 | N4: 004740 | O4: NYM | P4: 9314DA31
A5: 142639 | B5: 46063 | C5: 65702071110 | D5: ACCU-CHEK GUIDE IN VITRO STRIP | E5: 50 | F5: 100 | G5: 2 | H5: 40 | I5: 28.61 | J5: 0 | K5: 7.15 | L5: 35.76 | M5: -4.24 | N5: 610014 | O5: ESI | P5: MEDDPRIME | Q5: 2FFA
A6: 130956 | B6: 46060 | C6: 65702071110 | D6: ACCU-CHEK GUIDE IN VITRO STRIP | E6: 50 | F6: 200 | G6: 4 | H6: 80 | I6: 71.52 | J6: 0 | K6: 0 | L6: 71.52 | M6: -8.48 | N6: 610014 | O6: ESI | P6: MEDDPRIME | Q6: 2FFA
A7: 107242 | B7: 46062 | C7: 65702071110 | D7: ACCU-CHEK GUIDE IN VITRO STRIP | E7: 50 | F7: 100 | G7: 2 | H7: 40 | I7: 39.07 | J7: 0 | K7: 0 | L7: 39.07 | M7: -0.93 | N7: 610502 | O7: CVS | P7: MEDDAET | Q7: RXAETD
A8: 145278 | B8: 46081 | C8: 65702071110 | D8: ACCU-CHEK GUIDE IN VITRO STRIP | E8: 50 | F8: 200 | G8: 4 | H8: 80 | I8: 67.95 | J8: 0 | K8: 7.55 | L8: 75.5 | M8: -4.5 | N8: 015581 | O8: ARG/HUM | P8: 3200000 | Q8: Y9035
A9: 124196 | B9: 46062 | C9: 65702071110 | D9: ACCU-CHEK GUIDE IN VITRO STRIP | E9: 50 | F9: 100 | G9: 2 | H9: 40 | I9: 35.38 | J9: 0 | K9: 0 | L9: 35.38 | M9: -4.62 | N9: 610014 | O9: ESI | P9: MEDDPRIME | Q9: 2FFA
A10: 123286 | B10: 46077 | C10: 65702071110 | D10: ACCU-CHEK GUIDE IN VITRO STRIP | E10: 50 | F10: 100 | G10: 2 | H10: 40 | I10: 28.61 | J10: 0 | K10: 7.15 | L10: 35.76 | M10: -4.24 | N10: 610014 | O10: ESI | P10: MEDDPRIME | Q10: 2FFA
A11: 141797 | B11: 46057 | C11: 65702071110 | D11: ACCU-CHEK GUIDE IN VITRO STRIP | E11: 50 | F11: 100 | G11: 2 | H11: 40 | I11: 39.07 | J11: 0 | K11: 0 | L11: 39.07 | M11: -0.93 | N11: 610502 | O11: CVS | P11: MEDDAET | Q11: RXAETD
A12: 143274 | B12: 46066 | C12: 65702072910 | D12: ACCU-CHEK GUIDE W/DEVICE KIT | E12: 1 | F12: 1 | G12: 1 | H12: 26 | I12: 21.18 | J12: 0 | K12: 0 | L12: 21.18 | M12: -4.82 | N12: 610014 | O12: ESI | P12: MEDDPRIME | Q12: 2FFA
A13: 143916 | B13: 46071 | C13: 50924097110 | D13: ACCU-CHEK SOFTCLIX LANCETS | E13: 100 | F13: 200 | G13: 2 | H13: 0 | I13: 19 | J13: 0 | K13: 0 | L13: 19 | M13: 0 | N13: 004336 | O13: CVS | P13: ADV | Q13: RX7682
A14: 139434 | B14: 46066 | C14: 50924097110 | D14: ACCU-CHEK SOFTCLIX LANCETS | E14: 100 | F14: 100 | G14: 1 | H14: 0 | I14: 11.61 | J14: 0 | K14: 0 | L14: 11.61 | M14: 0 | N14: 004336 | O14: CVS | P14: ADV | Q14: RX7682
A15: 144127 | B15: 46072 | C15: 45802073230 | D15: ACETAMINOPHEN 120 MG RECTAL SUPPOSITORY | E15: 12 | F15: 12 | G15: 1 | H15: 0 | I15: 12.39 | J15: 0 | K15: 0 | L15: 12.39 | M15: 0 | N15: 004740 | O15: NYM | P15: 9314DA31
A16: 137297 | B16: 46070 | C16: 57237030412 | D16: ACETAMINOPHEN 160 MG/5ML ORAL SOLUTION | E16: 118 | F16: 354 | G16: 3 | H16: 9 | I16: 13.7 | J16: 0 | K16: 0 | L16: 13.7 | M16: 4.7 | N16: 004740 | O16: NYM | P16: 9314DA31
A17: 144897 | B17: 46079 | C17: 00536132701 | D17: ACETAMINOPHEN 325 MG TABLET * TYLENOL REGULAR | E17: 100 | F17: 30 | G17: 0.3 | H17: 0 | I17: 10.58 | J17: 0 | K17: 0 | L17: 10.58 | M17: 0 | N17: 004740 | O17: NYM | P17: 9314DA31
A18: 143037 | B18: 46065 | C18: 00536132701 | D18: ACETAMINOPHEN 325 MG TABLET * TYLENOL REGULAR | E18: 100 | F18: 100 | G18: 1 | H18: 0 | I18: 11.5 | J18: 0 | K18: 0 | L18: 11.5 | M18: 0 | N18: 004740 | O18: NYM | P18: 9314DA31
A19: 141396 | B19: 46055 | C19: 00536132701 | D19: ACETAMINOPHEN 325 MG TABLET * TYLENOL REGULAR | E19: 100 | F19: 30 | G19: 0.3 | H19: 0 | I19: 10.58 | J19: 0 | K19: 0 | L19: 10.58 | M19: 0 | N19: 004740 | O19: NYM | P19: 9314DA31
A20: 142945 | B20: 46064 | C20: 00536132710 | D20: ACETAMINOPHEN 325MG TABLET | E20: 1000 | F20: 30 | G20: 0.03 | H20: 0 | I20: 0 | J20: 0 | K20: 0 | L20: 0 | M20: 0 | N20: 000000
A21: 142433 | B21: 46062 | C21: 00536132710 | D21: ACETAMINOPHEN 325MG TABLET | E21: 1000 | F21: 100 | G21: 0.1 | H21: 0 | I21: 11.5 | J21: 0 | K21: 0 | L21: 11.5 | M21: 0 | N21: 004740 | O21: NYM | P21: 9314DA31
A22: 143096 | B22: 46065 | C22: 00536132710 | D22: ACETAMINOPHEN 325MG TABLET | E22: 1000 | F22: 60 | G22: 0.06 | H22: 0 | I22: 10.97 | J22: 0 | K22: 0 | L22: 10.97 | M22: 0 | N22: 004740 | O22: NYM | P22: 9314DA31
A23: 142336 | B23: 46062 | C23: 00536132710 | D23: ACETAMINOPHEN 325MG TABLET | E23: 1000 | F23: 120 | G23: 0.12 | H23: 0 | I23: 0.96 | J23: 0 | K23: 0 | L23: 0.96 | M23: 0 | N23: 004336 | O23: CVS | P23: ADV | Q23: RX1104
A24: 142179 | B24: 46059 | C24: 00536132710 | D24: ACETAMINOPHEN 325MG TABLET | E24: 1000 | F24: 24 | G24: 0.02 | H24: 0 | I24: 0 | J24: 0 | K24: 0 | L24: 0 | M24: 0 | N24: 000000
A25: 141820 | B25: 46057 | C25: 00536132710 | D25: ACETAMINOPHEN 325MG TABLET | E25: 1000 | F25: 60 | G25: 0.06 | H25: 0 | I25: 10.97 | J25: 0 | K25: 0 | L25: 10.97 | M25: 0 | N25: 004740 | O25: NYM | P25: 9314DA31
A26: 141820 | B26: 46069 | C26: 00536132710 | D26: ACETAMINOPHEN 325MG TABLET | E26: 1000 | F26: 60 | G26: 0.06 | H26: 0 | I26: 10.97 | J26: 0 | K26: 0 | L26: 10.97 | M26: 0 | N26: 004740 | O26: NYM | P26: 9314DA31
A27: 144412 | B27: 46076 | C27: 00536132710 | D27: ACETAMINOPHEN 325MG TABLET | E27: 1000 | F27: 240 | G27: 0.24 | H27: 0 | I27: 13.1 | J27: 0 | K27: 0 | L27: 13.1 | M27: 0 | N27: 004740 | O27: NYM | P27: 9314DA31
A28: 142473 | B28: 46062 | C28: 00536132710 | D28: ACETAMINOPHEN 325MG TABLET | E28: 1000 | F28: 28 | G28: 0.03 | H28: 0 | I28: 10.55 | J28: 0 | K28: 0 | L28: 10.55 | M28: 0 | N28: 004740 | O28: NYM | P28: 9314DA31
A29: 143773 | B29: 46071 | C29: 00536132710 | D29: ACETAMINOPHEN 325MG TABLET | E29: 1000 | F29: 30 | G29: 0.03 | H29: 0 | I29: 10.58 | J29: 0 | K29: 0 | L29: 10.58 | M29: 0 | N29: 004740 | O29: NYM | P29: 9314DA31
A30: 143264 | B30: 46066 | C30: 00904672080 | D30: ACETAMINOPHEN 500MG TABLET NYM | E30: 1000 | F30: 100 | G30: 0.1 | H30: 0 | I30: 11.67 | J30: 0 | K30: 0 | L30: 11.67 | M30: 0 | N30: 004740 | O30: NYM | P30: 9314DA31
A31: 144261 | B31: 46073 | C31: 00904672080 | D31: ACETAMINOPHEN 500MG TABLET NYM | E31: 1000 | F31: 30 | G31: 0.03 | H31: 0 | I31: 10.55 | J31: 0 | K31: 0 | L31: 10.55 | M31: 0 | N31: 004740 | O31: NYM | P31: 9314DA31
A32: 139101 | B32: 46064 | C32: 00904672080 | D32: ACETAMINOPHEN 500MG TABLET NYM | E32: 1000 | F32: 100 | G32: 0.1 | H32: 0 | I32: 11.67 | J32: 0 | K32: 0 | L32: 11.67 | M32: 0 | N32: 004740 | O32: NYM | P32: 9314DA31
A33: 143798 | B33: 46071 | C33: 00904672080 | D33: ACETAMINOPHEN 500MG TABLET NYM | E33: 1000 | F33: 180 | G33: 0.18 | H33: 0 | I33: 12.42 | J33: 0 | K33: 0 | L33: 12.42 | M33: 0 | N33: 004740 | O33: NYM | P33: 9314DA31
A34: 137945 | B34: 46057 | C34: 00904672080 | D34: ACETAMINOPHEN 500MG TABLET NYM | E34: 1000 | F34: 90 | G34: 0.09 | H34: 0 | I34: 11.52 | J34: 0 | K34: 0 | L34: 11.52 | M34: 0 | N34: 004740 | O34: NYM | P34: 9314DA31
A35: 142766 | B35: 46064 | C35: 00904672080 | D35: ACETAMINOPHEN 500MG TABLET NYM | E35: 1000 | F35: 60 | G35: 0.06 | H35: 0 | I35: 11.07 | J35: 0 | K35: 0 | L35: 11.07 | M35: 0 | N35: 004740 | O35: NYM | P35: 9314DA31
A36: 142836 | B36: 46064 | C36: 00904672080 | D36: ACETAMINOPHEN 500MG TABLET NYM | E36: 1000 | F36: 120 | G36: 0.12 | H36: 0 | I36: 11.97 | J36: 0 | K36: 0 | L36: 11.97 | M36: 0 | N36: 004740 | O36: NYM | P36: 9314DA31
... A41: 140749 | B41: 46077 | C41: 00904672080 | D41: ACETAMINOPHEN 500MG TABLET NYM | E41: 1000 | F41: 100 | G41: 0.1 | H41: 0 | I41: 11.17 | J41: 0 | K41: 0 | L41: 11.17 | M41: 0 | N41: 004740 | O41: NYM | P41: 9314DA31
A42: 143083 | B42: 46065 | C42: 00904672080 | D42: ACETAMINOPHEN 500MG TABLET NYM | E42: 1000 | F42: 120 | G42: 0.12 | H42: 0 | I42: 0 | J42: 0 | K42: 0 | L42: 0 | M42: 0 | N42: 000000
A43: 141493 | B43: 46055 | C43: 00904672080 | D43: ACETAMINOPHEN 500MG TABLET NYM | E43: 1000 | F43: 200 | G43: 0.2 | H43: 0 | I43: 13.16 | J43: 0 | K43: 0 | L43: 13.16 | M43: 0 | N43: 004740 | O43: NYM | P43: 9314DA31
A44: 143167 | B44: 46065 | C44: 00904672080 | D44: ACETAMINOPHEN 500MG TABLET NYM | E44: 1000 | F44: 30 | G44: 0.03 | H44: 0 | I44: 10.63 | J44: 0 | K44: 0 | L44: 10.63 | M44: 0 | N44: 004740 | O44: NYM | P44: 9314DA31
...

Sheet RX Comparison +ve
A1: RX Comparision +ve Analysis (All RXs)
A2: RX | B2: Fill Date | C2: NDC | D2: Drug Name | E2: Pkg Size | F2: Qty Filled | G2: Package Billed | H2: Kinray Final Price | I2: Ins Paid | J2: SDRA Amt | K2: COPAY | L2: Total = (Ins Paid + SDRA + COPAY) | M2: Difference | N2: BIN | O2: Processor | P2: PCN | Q2: Group
A3: 144533 | B3: 46077 | C3: 59148000713 | D3: ABILIFY 5MG TABLET | E3: 30 | F3: 30 | G3: 1 | H3: 568 | I3: 570.77 | J3: 0 | K3: 0 | L3: 570.77 | M3: 2.77 | N3: 004740 | O3: NYM | P3: 9314DA31
A4: 137297 | B4: 46070 | C4: 57237030412 | D4: ACETAMINOPHEN 160 MG/5ML ORAL SOLUTION | E4: 118 | F4: 354 | G4: 3 | H4: 9 | I4: 13.7 | J4: 0 | K4: 0 | L4: 13.7 | M4: 4.7 | N4: 004740 | O4: NYM | P4: 9314DA31
A5: 125941 | B5: 46065 | C5: 45802020126 | D5: ACETAMINOPHEN CHILDRENS 160 MG/5ML ORAL SUSPENSION | E5: 118 | F5: 118 | G5: 1 | H5: 3 | I5: 11.33 | J5: 0 | K5: 0 | L5: 11.33 | M5: 8.33 | N5: 004740 | O5: NYM | P5: 9314DA31
A6: 145131 | B6: 46080 | C6: 00904731427 | D6: ACETAMINOPHEN ER 650MG TABLET ER | E6: 400 | F6: 24 | G6: 0.06 | H6: 1.98 | I6: 11.27 | J6: 0 | K6: 0 | L6: 11.27 | M6: 9.29 | N6: 004740 | O6: NYM | P6: 9314DA31
A7: 140034 | B7: 46071 | C7: 00904731427 | D7: ACETAMINOPHEN ER 650MG TABLET ER | E7: 400 | F7: 60 | G7: 0.15 | H7: 4.95 | I7: 12.91 | J7: 0 | K7: 0 | L7: 12.91 | M7: 7.96 | N7: 004740 | O7: NYM | P7: 9314DA31
A8: 143452 | B8: 46069 | C8: 00904731427 | D8: ACETAMINOPHEN ER 650MG TABLET ER | E8: 400 | F8: 60 | G8: 0.15 | H8: 4.95 | I8: 12.91 | J8: 0 | K8: 0 | L8: 12.91 | M8: 7.96 | N8: 004740 | O8: NYM | P8: 9314DA31
A9: 142001 | B9: 46058 | C9: 00904731427 | D9: ACETAMINOPHEN ER 650MG TABLET ER | E9: 400 | F9: 30 | G9: 0.07 | H9: 2.48 | I9: 11.54 | J9: 0 | K9: 0 | L9: 11.54 | M9: 9.06 | N9: 004740 | O9: NYM | P9: 9314DA31
A10: 141223 | B10: 46079 | C10: 00904731427 | D10: ACETAMINOPHEN ER 650MG TABLET ER | E10: 400 | F10: 180 | G10: 0.45 | H10: 14.85 | I10: 18.36 | J10: 0 | K10: 0 | L10: 18.36 | M10: 3.51 | N10: 004740 | O10: NYM | P10: 9314DA31
A11: 143260 | B11: 46066 | C11: 00904731427 | D11: ACETAMINOPHEN ER 650MG TABLET ER | E11: 400 | F11: 30 | G11: 0.07 | H11: 2.48 | I11: 11.54 | J11: 0 | K11: 0 | L11: 11.54 | M11: 9.06 | N11: 004740 | O11: NYM | P11: 9314DA31
A12: 145232 | B12: 46080 | C12: 00904731427 | D12: ACETAMINOPHEN ER 650MG TABLET ER | E12: 400 | F12: 24 | G12: 0.06 | H12: 1.98 | I12: 11.27 | J12: 0 | K12: 0 | L12: 11.27 | M12: 9.29 | N12: 004740 | O12: NYM | P12: 9314DA31
A13: 144182 | B13: 46073 | C13: 00904731427 | D13: ACETAMINOPHEN ER 650MG TABLET ER | E13: 400 | F13: 40 | G13: 0.1 | H13: 3.3 | I13: 12 | J13: 0 | K13: 0 | L13: 12 | M13: 8.7 | N13: 004740 | O13: NYM | P13: 9314DA31
A14: 140888 | B14: 46078 | C14: 00904731427 | D14: ACETAMINOPHEN ER 650MG TABLET ER | E14: 400 | F14: 100 | G14: 0.25 | H14: 8.25 | I14: 14.72 | J14: 0 | K14: 0 | L14: 14.72 | M14: 6.47 | N14: 004740 | O14: NYM | P14: 9314DA31
... A20: 143556 | B20: 46069 | C20: 00310908012 | D20: AIRSUPRA 90-80 MCG/ACT INHALATION AEROSOL | E20: 10.7 | F20: 10.7 | G20: 1 | H20: 490 | I20: 493.53 | J20: 0 | K20: 0 | L20: 493.53 | M20: 3.53 | N20: 004740 | O20: NYM | P20: 9314DA31
A21: 143439 | B21: 46069 | C21: 66993001968 | D21: ALBUTEROL HFA 108 MCG/AC (VENTOLIN 18GM) | E21: 18 | F21: 54 | G21: 3 | H21: 123 | I21: 135.54 | J21: 0 | K21: 0 | L21: 135.54 | M21: 12.54 | N21: 015574 | O21: MEDIMP | P21: ASPROD1 | Q21: VNS01
A22: 144483 | B22: 46076 | C22: 66993001968 | D22: ALBUTEROL HFA 108 MCG/AC (VENTOLIN 18GM) | E22: 18 | F22: 18 | G22: 1 | H22: 41 | I22: 43.73 | J22: 0 | K22: 1.6 | L22: 45.33 | M22: 4.33 | N22: 015574 | O22: MEDIMP | P22: ASPROD1
A23: 133322 | B23: 46077 | C23: 68180096301 | D23: ALBUTEROL SULFATE HFA 108 (90 BASE)MCG/ACT AEROSOL | E23: 8.5 | F23: 8.5 | G23: 1 | H23: 13 | I23: 24.72 | J23: 0 | K23: 0 | L23: 24.72 | M23: 11.72 | N23: 004740 | O23: NYM | P23: 9314DA31
A24: 142513 | B24: 46063 | C24: 68180096301 | D24: ALBUTEROL SULFATE HFA 108 (90 BASE)MCG/ACT AEROSOL | E24: 8.5 | F24: 17 | G24: 2 | H24: 26 | I24: 39.25 | J24: 0 | K24: 0 | L24: 39.25 | M24: 13.25 | N24: 004740 | O24: NYM | P24: 9314DA31
A25: 144869 | B25: 46079 | C25: 68180096301 | D25: ALBUTEROL SULFATE HFA 108 (90 BASE)MCG/ACT AEROSOL | E25: 8.5 | F25: 25.5 | G25: 3 | H25: 39 | I25: 50.66 | J25: 0 | K25: 0 | L25: 50.66 | M25: 11.66 | N25: 004336 | O25: CVS | P25: MEDDADV | Q25: RX1110
A26: 142667 | B26: 46064 | C26: 68180096301 | D26: ALBUTEROL SULFATE HFA 108 (90 BASE)MCG/ACT AEROSOL | E26: 8.5 | F26: 25.5 | G26: 3 | H26: 39 | I26: 53.79 | J26: 0 | K26: 0 | L26: 53.79 | M26: 14.79 | N26: 004740 | O26: NYM | P26: 9314DA31
A27: 140647 | B27: 46078 | C27: 68180096301 | D27: ALBUTEROL SULFATE HFA 108 (90 BASE)MCG/ACT AEROSOL | E27: 8.5 | F27: 8.5 | G27: 1 | H27: 13 | I27: 20.08 | J27: 0 | K27: 0 | L27: 20.08 | M27: 7.08 | N27: 017010 | O27: ESI | P27: 0518GWH | Q27: CIGUG0000631676
A28: 139811 | B28: 46070 | C28: 68180096301 | D28: ALBUTEROL SULFATE HFA 108 (90 BASE)MCG/ACT AEROSOL | E28: 8.5 | F28: 8.5 | G28: 1 | H28: 13 | I28: 16.76 | J28: 0 | K28: 0 | L28: 16.76 | M28: 3.76 | N28: 004336 | O28: CVS | P28: MEDDADV | Q28: RX1110
A29: 140836 | B29: 46078 | C29: 68180096301 | D29: ALBUTEROL SULFATE HFA 108 (90 BASE)MCG/ACT AEROSOL | E29: 8.5 | F29: 8.5 | G29: 1 | H29: 13 | I29: 15.16 | J29: 0 | K29: 1.6 | L29: 16.76 | M29: 3.76 | N29: 004336 | O29: CVS | P29: MEDDADV | Q29: RX1110
A30: 142632 | B30: 46063 | C30: 68180096301 | D30: ALBUTEROL SULFATE HFA 108 (90 BASE)MCG/ACT AEROSOL | E30: 8.5 | F30: 25.5 | G30: 3 | H30: 39 | I30: 49.06 | J30: 0 | K30: 1.6 | L30: 50.66 | M30: 11.66 | N30: 004336 | O30: CVS | P30: MEDDADV | Q30: RX1110
A31: 142675 | B31: 46064 | C31: 68180096301 | D31: ALBUTEROL SULFATE HFA 108 (90 BASE)MCG/ACT AEROSOL | E31: 8.5 | F31: 8.5 | G31: 1 | H31: 13 | I31: 16.76 | J31: 0 | K31: 0 | L31: 16.76 | M31: 3.76 | N31: 004336 | O31: CVS | P31: MEDDADV | Q31: RX1110
A32: 135594 | B32: 46077 | C32: 68180096301 | D32: ALBUTEROL SULFATE HFA 108 (90 BASE)MCG/ACT AEROSOL | E32: 8.5 | F32: 8.5 | G32: 1 | H32: 13 | I32: 24.72 | J32: 0 | K32: 0 | L32: 24.72 | M32: 11.72 | N32: 004740 | O32: NYM | P32: 9314DA31
A33: 103719 | B33: 46078 | C33: 68180096301 | D33: ALBUTEROL SULFATE HFA 108 (90 BASE)MCG/ACT AEROSOL | E33: 8.5 | F33: 8.5 | G33: 1 | H33: 13 | I33: 24.72 | J33: 0 | K33: 0 | L33: 24.72 | M33: 11.72 | N33: 004740 | O33: NYM | P33: 9314DA31
A34: 134546 | B34: 46057 | C34: 68180096301 | D34: ALBUTEROL SULFATE HFA 108 (90 BASE)MCG/ACT AEROSOL | E34: 8.5 | F34: 8.5 | G34: 1 | H34: 13 | I34: 16.76 | J34: 0 | K34: 0 | L34: 16.76 | M34: 3.76 | N34: 004336 | O34: CVS | P34: MEDDADV | Q34: RX1110
A35: 123579 | B35: 46057 | C35: 68180096301 | D35: ALBUTEROL SULFATE HFA 108 (90 BASE)MCG/ACT AEROSOL | E35: 8.5 | F35: 17 | G35: 2 | H35: 26 | I35: 28.3 | J35: 0 | K35: 0 | L35: 28.3 | M35: 2.3 | N35: 610502 | O35: CVS | P35: MEDDAET | Q35: RXAETD
A36: 143012 | B36: 46065 | C36: 68180096301 | D36: ALBUTEROL SULFATE HFA 108 (90 BASE)MCG/ACT AEROSOL | E36: 8.5 | F36: 25.5 | G36: 3 | H36: 39 | I36: 54.06 | J36: 0 | K36: 5.1 | L36: 59.16 | M36: 20.16 | N36: 015574 | O36: MEDIMP | P36: ASPROD1 | Q36: VNS01
A37: 139283 | B37: 46065 | C37: 68180096301 | D37: ALBUTEROL SULFATE HFA 108 (90 BASE)MCG/ACT AEROSOL | E37: 8.5 | F37: 8.5 | G37: 1 | H37: 13 | I37: 24.72 | J37: 0 | K37: 0 | L37: 24.72 | M37: 11.72 | N37: 004740 | O37: NYM | P37: 9314DA31
A38: 144542 | B38: 46077 | C38: 68180096301 | D38: ALBUTEROL SULFATE HFA 108 (90 BASE)MCG/ACT AEROSOL | E38: 8.5 | F38: 8.5 | G38: 1 | H38: 13 | I38: 24.72 | J38: 0 | K38: 0 | L38: 24.72 | M38: 11.72 | N38: 004740 | O38: NYM | P38: 9314DA31
A39: 137916 | B39: 46057 | C39: 68180096301 | D39: ALBUTEROL SULFATE HFA 108 (90 BASE)MCG/ACT AEROSOL | E39: 8.5 | F39: 17 | G39: 2 | H39: 26 | I39: 41.27 | J39: 0 | K39: 0 | L39: 41.27 | M39: 15.27 | N39: 004740 | O39: NYM | P39: 9314DA31
A40: 132279 | B40: 46065 | C40: 68180096301 | D40: ALBUTEROL SULFATE HFA 108 (90 BASE)MCG/ACT AEROSOL | E40: 8.5 | F40: 8.5 | G40: 1 | H40: 13 | I40: 24.72 | J40: 0 | K40: 0 | L40: 24.72 | M40: 11.72 | N40: 004740 | O40: NYM | P40: 9314DA31
A41: 143256 | B41: 46066 | C41: 68180096301 | D41: ALBUTEROL SULFATE HFA 108 (90 BASE)MCG/ACT AEROSOL | E41: 8.5 | F41: 8.5 | G41: 1 | H41: 13 | I41: 24.72 | J41: 0 | K41: 0 | L41: 24.72 | M41: 11.72 | N41: 004740 | O41: NYM | P41: 9314DA31
A42: 143341 | B42: 46066 | C42: 68180096301 | D42: ALBUTEROL SULFATE HFA 108 (90 BASE)MCG/ACT AEROSOL | E42: 8.5 | F42: 8.5 | G42: 1 | H42: 13 | I42: 24.72 | J42: 0 | K42: 0 | L42: 24.72 | M42: 11.72 | N42: 004740 | O42: NYM | P42: 9314DA31
A43: 107399 | B43: 46065 | C43: 68180096301 | D43: ALBUTEROL SULFATE HFA 108 (90 BASE)MCG/ACT AEROSOL | E43: 8.5 | F43: 8.5 | G43: 1 | H43: 13 | I43: 18.27 | J43: 0 | K43: 1.6 | L43: 19.87 | M43: 6.87 | N43: 015574 | O43: MEDIMP | P43: ASPROD1 | Q43: VNS01
A44: 137903 | B44: 46056 | C44: 68180096301 | D44: ALBUTEROL SULFATE HFA 108 (90 BASE)MCG/ACT AEROSOL | E44: 8.5 | F44: 8.5 | G44: 1 | H44: 13 | I44: 11.66 | J44: 0 | K44: 5.1 | L44: 16.76 | M44: 3.76 | N44: 004336 | O44: CVS | P44: MEDDADV | Q44: RX8585
A45: 137835 | B45: 46056 | C45: 68180096301 | D45: ALBUTEROL SULFATE HFA 108 (90 BASE)MCG/ACT AEROSOL | E45: 8.5 | F45: 17 | G45: 2 | H45: 26 | I45: 89.02 | J45: 0 | K45: 10 | L45: 99.02 | M45: 73.02 | N45: 610011 | O45: OPTUM | P45: IRX | Q45: 32BJRX
...

Sheet MFP Drugs - RX
A1: MFP DRUGS
A2: RX | B2: Fill Date | C2: NDC | D2: Drug Name | E2: Pkg Size | F2: Qty Filled | G2: Package billed | H2: Kinray Unit Price | I2: Kinray Final Price | J2: Ins Paid Plan 1 | K2: Ins Paid Plan 2 | L2: SDRA Amt | M2: COPAY | N2: Winning Ins Paid | O2: Total Collected | P2: Difference | Q2: BIN | R2: Processor | S2: PCN | T2: Group
A3: 145123 | B3: 46080 | C3: 66993045730 | D3: DAPAGLIFLOZIN PROPANEDIOL 10MG TABLET | E3: 30 | F3: 90 | G3: 3 | H3: 440 | I3: 1320 | J3: 544.42 | K3: 0 | L3: 590.62 | M3: 0 | N3: 544.42 | O3: 1135.04 | P3: -184.96 | Q3: 004336 | R3: CVS | S3: MEDDADV | T3: RX1110
A4: 144175 | B4: 46073 | C4: 66993045730 | D4: DAPAGLIFLOZIN PROPANEDIOL 10MG TABLET | E4: 30 | F4: 90 | G4: 3 | H4: 440 | I4: 1320 | J4: 542.82 | K4: 0 | L4: 590.62 | M4: 1.6 | N4: 542.82 | O4: 1135.04 | P4: -184.96 | Q4: 004336 | R4: CVS | S4: MEDDADV | T4: RX1110
A5: 143965 | B5: 46072 | C5: 66993045730 | D5: DAPAGLIFLOZIN PROPANEDIOL 10MG TABLET | E5: 30 | F5: 90 | G5: 3 | H5: 440 | I5: 1320 | J5: 549.45 | K5: 0 | L5: 590.62 | M5: 0 | N5: 549.45 | O5: 1140.07 | P5: -179.93 | Q5: 015574 | R5: MEDIMP | S5: ASPROD1 | T5: VNS01
A6: 142686 | B6: 46064 | C6: 66993045730 | D6: DAPAGLIFLOZIN PROPANEDIOL 10MG TABLET | E6: 30 | F6: 90 | G6: 3 | H6: 440 | I6: 1320 | J6: 542.82 | K6: 0 | L6: 590.62 | M6: 1.6 | N6: 542.82 | O6: 1135.04 | P6: -184.96 | Q6: 004336 | R6: CVS | S6: MEDDADV | T6: RX1110
A7: 142705 | B7: 46064 | C7: 66993045730 | D7: DAPAGLIFLOZIN PROPANEDIOL 10MG TABLET | E7: 30 | F7: 90 | G7: 3 | H7: 440 | I7: 1320 | J7: 544.42 | K7: 0 | L7: 590.62 | M7: 0 | N7: 544.42 | O7: 1135.04 | P7: -184.96 | Q7: 004336 | R7: CVS | S7: MEDDADV | T7: RX1110
A8: 142895 | B8: 46064 | C8: 66993045730 | D8: DAPAGLIFLOZIN PROPANEDIOL 10MG TABLET | E8: 30 | F8: 30 | G8: 1 | H8: 440 | I8: 440 | J8: 181.35 | K8: 0 | L8: 196.87 | M8: 0 | N8: 181.35 | O8: 378.22 | P8: -61.78 | Q8: 004336 | R8: CVS | S8: MEDDADV | T8: RX1110
A9: 142291 | B9: 46062 | C9: 66993045730 | D9: DAPAGLIFLOZIN PROPANEDIOL 10MG TABLET | E9: 30 | F9: 90 | G9: 3 | H9: 440 | I9: 1320 | J9: 544.42 | K9: 0 | L9: 590.62 | M9: 0 | N9: 544.42 | O9: 1135.04 | P9: -184.96 | Q9: 004336 | R9: CVS | S9: MEDDADV | T9: RX1110
A10: 145170 | B10: 46080 | C10: 66993045630 | D10: DAPAGLIFLOZIN PROPANEDIOL 5MG TABLET | E10: 30 | F10: 90 | G10: 3 | H10: 0 | I10: 0 | J10: 544.42 | K10: 0 | L10: 590.62 | M10: 0 | N10: 544.42 | O10: 1135.04 | P10: 1135.04 | Q10: 004336 | R10: CVS | S10: MEDDADV | T10: RX1110
A11: 142521 | B11: 46063 | C11: 66993045630 | D11: DAPAGLIFLOZIN PROPANEDIOL 5MG TABLET | E11: 30 | F11: 30 | G11: 1 | H11: 0 | I11: 0 | J11: 181.35 | K11: 0 | L11: 196.87 | M11: 0 | N11: 181.35 | O11: 378.22 | P11: 378.22 | Q11: 004336 | R11: CVS | S11: MEDDADV | T11: RX1110
A12: 132589 | B12: 46073 | C12: 00003089321 | D12: ELIQUIS 2.5MG TAB | E12: 60 | F12: 180 | G12: 3 | H12: 336 | I12: 1008 | J12: 740.87 | K12: 0 | L12: 290.66 | M12: 4.9 | N12: 740.87 | O12: 1036.43 | P12: 28.43 | Q12: 004336 | R12: CVS | S12: MEDDADV | T12: RX1110
A13: 120419 | B13: 46066 | C13: 00003089321 | D13: ELIQUIS 2.5MG TAB | E13: 60 | F13: 180 | G13: 3 | H13: 336 | I13: 1008 | J13: 745.77 | K13: 0 | L13: 290.66 | M13: 0 | N13: 745.77 | O13: 1036.43 | P13: 28.43 | Q13: 004336 | R13: CVS | S13: MEDDADV | T13: RX8585
A14: 123970 | B14: 46062 | C14: 00003089321 | D14: ELIQUIS 2.5MG TAB | E14: 60 | F14: 60 | G14: 1 | H14: 336 | I14: 336 | J14: 243.56 | K14: 0 | L14: 96.89 | M14: 4.9 | N14: 243.56 | O14: 345.35 | P14: 9.35 | Q14: 004336 | R14: CVS | S14: MEDDADV | T14: RX8541
... A24: 123048 | B24: 46055 | C24: 00003089421 | D24: ELIQUIS 5MG TAB | E24: 60 | F24: 60 | G24: 1 | H24: 336 | I24: 336 | J24: 248.46 | K24: 0 | L24: 96.89 | M24: 0 | N24: 248.46 | O24: 345.35 | P24: 9.35 | Q24: 004336 | R24: CVS | S24: MEDDADV | T24: RX1110
A25: 121812 | B25: 46055 | C25: 00310621030 | D25: FARXIGA 10MG TABLET | E25: 30 | F25: 30 | G25: 1 | H25: 367 | I25: 367 | J25: 181.38 | K25: 0 | L25: 196.23 | M25: 4.9 | N25: 181.38 | O25: 382.51 | P25: 15.51 | Q25: 015574 | R25: MEDIMP | S25: ASPROD1
A26: 142782 | B26: 46064 | C26: 73070010315 | D26: INSULIN ASPART FLEXPEN 100 UNIT/ML SUBCUTANEOUS SOLUTION PEN-INJECTOR | E26: 15 | F26: 18 | G26: 1.2 | H26: 0 | I26: 0 | J26: 80.27 | K26: 0 | L26: 87.04 | M26: 0 | N26: 80.27 | O26: 167.31 | P26: 167.31 | Q26: 004336 | R26: CVS | S26: MEDDADV | T26: RX1110
A27: 143116 | B27: 46065 | C27: 00006027731 | D27: JANUVIA 100MG TAB | E27: 30 | F27: 90 | G27: 3 | H27: 321 | I27: 963 | J27: 346.47 | K27: 0 | L27: 638.29 | M27: 4.9 | N27: 346.47 | O27: 989.66 | P27: 26.66 | Q27: 004336 | R27: CVS | S27: MEDDADV | T27: RX1110
A28: 138331 | B28: 46064 | C28: 00006027731 | D28: JANUVIA 100MG TAB | E28: 30 | F28: 90 | G28: 3 | H28: 321 | I28: 963 | J28: 351.37 | K28: 0 | L28: 638.29 | M28: 0 | N28: 351.37 | O28: 989.66 | P28: 26.66 | Q28: 004336 | R28: CVS | S28: MEDDADV | T28: RX8585
A29: 130807 | B29: 46060 | C29: 00006027731 | D29: JANUVIA 100MG TAB | E29: 30 | F29: 90 | G29: 3 | H29: 321 | I29: 963 | J29: 351.37 | K29: 0 | L29: 638.29 | M29: 0 | N29: 351.37 | O29: 989.66 | P29: 26.66 | Q29: 004336 | R29: CVS | S29: MEDDADV | T29: RX1110
A30: 119371 | B30: 46059 | C30: 00006027731 | D30: JANUVIA 100MG TAB | E30: 30 | F30: 90 | G30: 3 | H30: 321 | I30: 963 | J30: 346.47 | K30: 0 | L30: 638.29 | M30: 4.9 | N30: 346.47 | O30: 989.66 | P30: 26.66 | Q30: 004336 | R30: CVS | S30: MEDDADV | T30: RX1110
A31: 137678 | B31: 46056 | C31: 00006027731 | D31: JANUVIA 100MG TAB | E31: 30 | F31: 30 | G31: 1 | H31: 321 | I31: 321 | J31: 117 | K31: 0 | L31: 212.76 | M31: 0 | N31: 117 | O31: 329.76 | P31: 8.76 | Q31: 004336 | R31: CVS | S31: MEDDADV | T31: RX1110
A32: 144507 | B32: 46077 | C32: 00006022131 | D32: JANUVIA 25MG TABLET | E32: 30 | F32: 30 | G32: 1 | H32: 0 | I32: 0 | J32: 127.74 | K32: 0 | L32: 212.76 | M32: 0 | N32: 127.74 | O32: 340.5 | P32: 340.5 | Q32: 017010 | R32: ESI | S32: CIMCARE | T32: CIGPDPRX
A33: 116072 | B33: 46077 | C33: 00006011231 | D33: JANUVIA 50MG TABLET | E33: 30 | F33: 30 | G33: 1 | H33: 321 | I33: 321 | J33: 113.34 | K33: 0 | L33: 212.76 | M33: 4.9 | N33: 113.34 | O33: 331 | P33: 10 | Q33: 610014 | R33: ESI | S33: MEDDPRIME | T33: 2FFA
A34: 131732 | B34: 46069 | C34: 00006011231 | D34: JANUVIA 50MG TABLET | E34: 30 | F34: 90 | G34: 3 | H34: 321 | I34: 963 | J34: 316.71 | K34: 0 | L34: 638.29 | M34: 45 | N34: 316.71 | O34: 1000 | P34: 37 | Q34: 610455 | R34: PRIMECAPRX | S34: NY4000 | T34: MAPD
A35: 142710 | B35: 46064 | C35: 00006011231 | D35: JANUVIA 50MG TABLET | E35: 30 | F35: 90 | G35: 3 | H35: 321 | I35: 963 | J35: 351.37 | K35: 0 | L35: 638.29 | M35: 0 | N35: 351.37 | O35: 989.66 | P35: 26.66 | Q35: 004336 | R35: CVS | S35: MEDDADV | T35: RX1110
A36: 142886 | B36: 46064 | C36: 00006011231 | D36: JANUVIA 50MG TABLET | E36: 30 | F36: 60 | G36: 2 | H36: 321 | I36: 642 | J36: 234.77 | K36: 0 | L36: 425.53 | M36: 0 | N36: 234.77 | O36: 660.3 | P36: 18.3 | Q36: 015599 | R36: ARG/HUM | S36: 5440000
A37: 142289 | B37: 46062 | C37: 00006011231 | D37: JANUVIA 50MG TABLET | E37: 30 | F37: 90 | G37: 3 | H37: 321 | I37: 963 | J37: 351.37 | K37: 0 | L37: 638.29 | M37: 0 | N37: 351.37 | O37: 989.66 | P37: 26.66 | Q37: 004336 | R37: CVS | S37: MEDDADV | T37: RX1110
A38: 145267 | B38: 46081 | C38: 00597015230 | D38: JARDIANCE 10MG TAB | E38: 30 | F38: 90 | G38: 3 | H38: 340 | I38: 1020 | J38: 607.56 | K38: 0 | L38: 438.54 | M38: 4.9 | N38: 607.56 | O38: 1051 | P38: 31 | Q38: 610014 | R38: ESI | S38: MEDDPRIME | T38: 2FGA
A39: 137349 | B39: 46079 | C39: 00597015230 | D39: JARDIANCE 10MG TAB | E39: 30 | F39: 30 | G39: 1 | H39: 340 | I39: 340 | J39: 203.58 | K39: 0 | L39: 146.18 | M39: 0 | N39: 203.58 | O39: 349.76 | P39: 9.76 | Q39: 004336 | R39: CVS | S39: MEDDADV | T39: RXCVSD
A40: 144564 | B40: 46077 | C40: 00597015230 | D40: JARDIANCE 10MG TAB | E40: 30 | F40: 90 | G40: 3 | H40: 340 | I40: 1020 | J40: 606.22 | K40: 0 | L40: 438.54 | M40: 4.9 | N40: 606.22 | O40: 1049.66 | P40: 29.66 | Q40: 004336 | R40: CVS | S40: MEDDADV | T40: RX1110
A41: 144395 | B41: 46076 | C41: 00597015230 | D41: JARDIANCE 10MG TAB | E41: 30 | F41: 30 | G41: 1 | H41: 340 | I41: 340 | J41: 203.61 | K41: 0 | L41: 146.18 | M41: 4.9 | N41: 203.61 | O41: 354.69 | P41: 14.69 | Q41: 015574 | R41: MEDIMP | S41: ASPROD1 | T41: VNS01
A42: 110099 | B42: 46072 | C42: 00597015230 | D42: JARDIANCE 10MG TAB | E42: 30 | F42: 90 | G42: 3 | H42: 340 | I42: 1020 | J42: 606.22 | K42: 0 | L42: 438.54 | M42: 4.9 | N42: 606.22 | O42: 1049.66 | P42: 29.66 | Q42: 004336 | R42: CVS | S42: MEDDADV | T42: RX1110
A43: 143416 | B43: 46069 | C43: 00597015230 | D43: JARDIANCE 10MG TAB | E43: 30 | F43: 90 | G43: 3 | H43: 340 | I43: 1020 | J43: 458.34 | K43: 0 | L43: 438.54 | M43: 152.78 | N43: 458.34 | O43: 1049.66 | P43: 29.66 | Q43: 004336 | R43: CVS | S43: MEDDADV | T43: RXCVSD
A44: 122708 | B44: 46063 | C44: 00597015230 | D44: JARDIANCE 10MG TAB | E44: 30 | F44: 60 | G44: 2 | H44: 340 | I44: 680 | J44: 407.4 | K44: 0 | L44: 292.36 | M44: 0 | N44: 407.4 | O44: 699.76 | P44: 19.76 | Q44: 004336 | R44: CVS | S44: MEDDADV | T44: RX8585
A45: 142599 | B45: 46063 | C45: 00597015230 | D45: JARDIANCE 10MG TAB | E45: 30 | F45: 90 | G45: 3 | H45: 340 | I45: 1020 | J45: 606.22 | K45: 0 | L45: 438.54 | M45: 4.9 | N45: 606.22 | O45: 1049.66 | P45: 29.66 | Q45: 004336 | R45: CVS | S45: MEDDADV | T45: RX1110
A46: 142421 | B46: 46062 | C46: 00597015230 | D46: JARDIANCE 10MG TAB | E46: 30 | F46: 90 | G46: 3 | H46: 340 | I46: 1020 | J46: 612.46 | K46: 0 | L46: 438.54 | M46: 0 | N46: 612.46 | O46: 1051 | P46: 31 | Q46: 610014 | R46: ESI | S46: MEDDPRIME | T46: 2FFA
A47: 130931 | B47: 46060 | C47: 00597015230 | D47: JARDIANCE 10MG TAB | E47: 30 | F47: 90 | G47: 3 | H47: 340 | I47: 1020 | J47: 606.22 | K47: 0 | L47: 438.54 | M47: 4.9 | N47: 606.22 | O47: 1049.66 | P47: 29.66 | Q47: 004336 | R47: CVS | S47: MEDDADV | T47: RX1110
A48: 142130 | B48: 46059 | C48: 00597015230 | D48: JARDIANCE 10MG TAB | E48: 30 | F48: 90 | G48: 3 | H48: 340 | I48: 1020 | J48: 571.17 | K48: 0 | L48: 438.54 | M48: 40 | N48: 571.17 | O48: 1049.71 | P48: 29.71 | Q48: 004336 | R48: CVS | S48: MEDDADV | T48: RXCVSD
... A64: 109458 | B64: 46065 | C64: 00597015330 | D64: JARDIANCE 25MG TAB | E64: 30 | F64: 90 | G64: 3 | H64: 340 | I64: 1020 | J64: 606.22 | K64: 0 | L64: 438.54 | M64: 4.9 | N64: 606.22 | O64: 1049.66 | P64: 29.66 | Q64: 004336 | R64: CVS | S64: MEDDADV | T64: RX1110
...

Sheet Summary
A1: Summary
A2: Summary of Trial 20 for the date range Feb 2026 - Feb 2026
A3: Metric | B3: ADAP | C3: ALL_PBM | D3: ARG/HUM | E3: CVS | F3: ESI | G3: FDS | H3: MEDIMP | I3: NYM | J3: OPTUM | K3: PRIMECAPRX | L3: TREDIUM
A4: Insurance $(BestRX) | B4: =SUM('Processed Data'!AO4:AO906) | C4: =SUM('Processed Data'!AN4:AN906) | D4: =SUM('Processed Data'!AP4:AP906) | E4: =SUM('Processed Data'!AQ4:AQ906) | F4: =SUM('Processed Data'!AR4:AR906) | G4: =SUM('Processed Data'!AS4:AS906) | H4: =SUM('Processed Data'!AT4:AT906) | I4: =SUM('Processed Data'!AU4:AU906) | J4: =SUM('Processed Data'!AV4:AV906) | K4: =SUM('Processed Data'!AW4:AW906) | L4: =SUM('Processed Data'!AX4:AX906)
A5: 100% $$ Purchased (Kinray) | B5: =SUM('Processed Data'!AZ4:AZ906) | C5: =SUM('Processed Data'!AY4:AY906) | D5: =SUM('Processed Data'!BA4:BA906) | E5: =SUM('Processed Data'!BB4:BB906) | F5: =SUM('Processed Data'!BC4:BC906) | G5: =SUM('Processed Data'!BD4:BD906) | H5: =SUM('Processed Data'!BE4:BE906) | I5: =SUM('Processed Data'!BF4:BF906) | J5: =SUM('Processed Data'!BG4:BG906) | K5: =SUM('Processed Data'!BH4:BH906) | L5: =SUM('Processed Data'!BI4:BI906)
A6: Net (Paid − Purchased) | B6: =SUM('Processed Data'!BK4:BK906) | C6: =SUM('Processed Data'!BJ4:BJ906) | D6: =SUM('Processed Data'!BL4:BL906) | E6: =SUM('Processed Data'!BM4:BM906) | F6: =SUM('Processed Data'!BN4:BN906) | G6: =SUM('Processed Data'!BO4:BO906) | H6: =SUM('Processed Data'!BP4:BP906) | I6: =SUM('Processed Data'!BQ4:BQ906) | J6: =SUM('Processed Data'!BR4:BR906) | K6: =SUM('Processed Data'!BS4:BS906) | L6: =SUM('Processed Data'!BT4:BT906)
A7: Needs to Ordered Sheet, Insurance-wise Order Estimate ($) | B7: =IFERROR(INDEX('Needs to be ordered - All'!$S$3:$S$678,MATCH("ADAP_D", 'Needs to be ordered - All'!$R$3:$R$678, 0)), 0) | C7: =IFERROR(INDEX('Needs to be ordered - All'!$S$3:$S$678,MATCH("ALL_PBM_D", 'Needs to be ordered - All'!$R$3:$R$678, 0)), 0) | D7: =IFERROR(INDEX('Needs to be ordered - All'!$S$3:$S$678,MATCH("ARG/HUM_D", 'Needs to be ordered - All'!$R$3:$R$678, 0)), 0) | E7: =IFERROR(INDEX('Needs to be ordered - All'!$S$3:$S$678,MATCH("CVS_D", 'Needs to be ordered - All'!$R$3:$R$678, 0)), 0) | F7: =IFERROR(INDEX('Needs to be ordered - All'!$S$3:$S$678,MATCH("ESI_D", 'Needs to be ordered - All'!$R$3:$R$678, 0)), 0) | G7: =IFERROR(INDEX('Needs to be ordered - All'!$S$3:$S$678,MATCH("FDS_D", 'Needs to be ordered - All'!$R$3:$R$678, 0)), 0) | H7: =IFERROR(INDEX('Needs to be ordered - All'!$S$3:$S$678,MATCH("MEDIMP_D", 'Needs to be ordered - All'!$R$3:$R$678, 0)), 0) | I7: =IFERROR(INDEX('Needs to be ordered - All'!$S$3:$S$678,MATCH("NYM_D", 'Needs to be ordered - All'!$R$3:$R$678, 0)), 0) | J7: =IFERROR(INDEX('Needs to be ordered - All'!$S$3:$S$678,MATCH("OPTUM_D", 'Needs to be ordered - All'!$R$3:$R$678, 0)), 0) | K7: =IFERROR(INDEX('Needs to be ordered - All'!$S$3:$S$678,MATCH("PRIMECAPRX_D", 'Needs to be ordered - All'!$R$3:$R$678, 0)), 0) | L7: =IFERROR(INDEX('Needs to be ordered - All'!$S$3:$S$678,MATCH("TREDIUM_D", 'Needs to be ordered - All'!$R$3:$R$678, 0)), 0)
