Workbook

Sheet Processed Data
A1: Hil (hh)
G2: Quantity Billed = BestRX | Q2: Package Size Billed = Quantity Billed(BestRx) ÷ Package Size | AA2: Package Size Difference = Total Packages Purchased(Vendors) − Package Size Billed(BestRx) | AK2: Actual $ Paid by Insurance = BestRX | AU2: Actual $ Purchased (Kinray Unit Price × Packages Billed To Ins) | BE2: Net(Profit/Loss)$ = Actual $ Paid(BestRx) − Actual $ Purchased(Kinray)
A3: NDC # | B3: Drug Name | C3: Package Size | D3: KINRAY | E3: Total Purchased | F3: Kinray_UPrice | G3: ALL_PBM_Q | H3: ARG/HUM_Q | I3: CAREMARK_Q | J3: EXPRESS_Q | K3: FDS_Q | L3: MEDIMP_Q | M3: NYM_Q | N3: OPTUM_Q | O3: PRIMECAPRX_Q | P3: RELAYHLTH_Q | Q3: ALL_PBM_P | R3: ARG/HUM_P | S3: CAREMARK_P | T3: EXPRESS_P | U3: FDS_P | V3: MEDIMP_P | W3: NYM_P | X3: OPTUM_P | Y3: PRIMECAPRX_P | Z3: RELAYHLTH_P | AA3: ALL_PBM_D | AB3: ARG/HUM_D | AC3: CAREMARK_D | AD3: EXPRESS_D | AE3: FDS_D | AF3: MEDIMP_D | AG3: NYM_D | AH3: OPTUM_D | AI3: PRIMECAPRX_D | AJ3: RELAYHLTH_D | AK3: ALL_PBM_T | AL3: ARG/HUM_T | AM3: CAREMARK_T | AN3: EXPRESS_T | AO3: FDS_T | AP3: MEDIMP_T | AQ3: NYM_T | AR3: OPTUM_T | AS3: PRIMECAPRX_T | AT3: RELAYHLTH_T | AU3: ALL_PBM_Pur | AV3: ARG/HUM_Pur | AW3: CAREMARK_Pur | AX3: EXPRESS_Pur | AY3: FDS_Pur | AZ3: MEDIMP_Pur | BA3: NYM_Pur | BB3: OPTUM_Pur | BC3: PRIMECAPRX_Pur | BD3: RELAYHLTH_Pur | BE3: ALL_PBM_Net | BF3: ARG/HUM_Net | BG3: CAREMARK_Net | BH3: EXPRESS_Net | BI3: FDS_Net | BJ3: MEDIMP_Net | BK3: NYM_Net | BL3: OPTUM_Net | BM3: PRIMECAPRX_Net | BN3: RELAYHLTH_Net
A4: 59148000713 | B4: ABILIFY 5MG TABLET | C4: 30 | D4: 2 | E4: 2 | F4: 563 | G4: 120 | H4: 0 | I4: 0 | J4: 0 | K4: 0 | L4: 0 | M4: 120 | N4: 0 | O4: 0 | P4: 0 | Q4: 4 | R4: 0 | S4: 0 | T4: 0 | U4: 0 | V4: 0 | W4: 4 | X4: 0 | Y4: 0 | Z4: 0 | AA4: -2 | AB4: 2 | AC4: 2 | AD4: 2 | AE4: 2 | AF4: 2 | AG4: -2 | AH4: 2 | AI4: 2 | AJ4: 2 | AK4: 2278 | AL4: 0 | AM4: 0 | AN4: 0 | AO4: 0 | AP4: 0 | AQ4: 2278 | AR4: 0 | AS4: 0 | AT4: 0 | AU4: 2252 | AV4: 0 | AW4: 0 | AX4: 0 | AY4: 0 | AZ4: 0 | BA4: 2252 | BB4: 0 | BC4: 0 | BD4: 0 | BE4: 26 | BF4: 0 | BG4: 0 | BH4: 0 | BI4: 0 | BJ4: 0 | BK4: 26 | BL4: 0 | BM4: 0 | BN4: 0
A5: 65702071110 | B5: ACCU-CHEK GUIDE IN VITRO STRIP | C5: 50 | D5: 22 | E5: 22 | F5: 20 | G5: 2100 | H5: 200 | I5: 700 | J5: 1100 | K5: 0 | L5: 0 | M5: 0 | N5: 100 | O5: 0 | P5: 0 | Q5: 42 | R5: 4 | S5: 14 | T5: 22 | U5: 0 | V5: 0 | W5: 0 | X5: 2 | Y5: 0 | Z5: 0 | AA5: -20 | AB5: 18 | AC5: 8 | AD5: 0 | AE5: 22 | AF5: 22 | AG5: 22 | AH5: 20 | AI5: 22 | AJ5: 22 | AK5: 785 | AL5: 68 | AM5: 247 | AN5: 364 | AO5: 0 | AP5: 0 | AQ5: 0 | AR5: 41 | AS5: 0 | AT5: 0 | AU5: 840 | AV5: 80 | AW5: 280 | AX5: 440 | AY5: 0 | AZ5: 0 | BA5: 0 | BB5: 40 | BC5: 0 | BD5: 0 | BE5: -55 | BF5: -12 | BG5: -33 | BH5: -76 | BI5: 0 | BJ5: 0 | BK5: 0 | BL5: 1 | BM5: 0 | BN5: 0
A6: 65702072910 | B6: ACCU-CHEK GUIDE W/DEVICE KIT | C6: 1 | D6: 3 | E6: 3 | F6: 26 | G6: 1 | H6: 0 | I6: 0 | J6: 1 | K6: 0 | L6: 0 | M6: 0 | N6: 0 | O6: 0 | P6: 0 | Q6: 1 | R6: 0 | S6: 0 | T6: 1 | U6: 0 | V6: 0 | W6: 0 | X6: 0 | Y6: 0 | Z6: 0 | AA6: 2 | AB6: 3 | AC6: 3 | AD6: 2 | AE6: 3 | AF6: 3 | AG6: 3 | AH6: 3 | AI6: 3 | AJ6: 3 | AK6: 21 | AL6: 0 | AM6: 0 | AN6: 21 | AO6: 0 | AP6: 0 | AQ6: 0 | AR6: 0 | AS6: 0 | AT6: 0 | AU6: 26 | AV6: 0 | AW6: 0 | AX6: 26 | AY6: 0 | AZ6: 0 | BA6: 0 | BB6: 0 | BC6: 0 | BD6: 0 | BE6: -5 | BF6: 0 | BG6: 0 | BH6: -5 | BI6: 0 | BJ6: 0 | BK6: 0 | BL6: 0 | BM6: 0 | BN6: 0
A7: 50242014301 | B7: ACTEMRA ACTPEN 162 MG/0.9ML SUBCUTANEOUS SOLUTION AUTO-INJECTOR | C7: 0.9 | D7: 6 | E7: 6 | F7: 1145 | G7: 5.4 | H7: 0 | I7: 0 | J7: 0 | K7: 0 | L7: 0 | M7: 5.4 | N7: 0 | O7: 0 | P7: 0 | Q7: 6 | R7: 0 | S7: 0 | T7: 0 | U7: 0 | V7: 0 | W7: 6 | X7: 0 | Y7: 0 | Z7: 0 | AA7: 0 | AB7: 6 | AC7: 6 | AD7: 6 | AE7: 6 | AF7: 6 | AG7: 0 | AH7: 6 | AI7: 6 | AJ7: 6 | AK7: 6927 | AL7: 0 | AM7: 0 | AN7: 0 | AO7: 0 | AP7: 0 | AQ7: 6927 | AR7: 0 | AS7: 0 | AT7: 0 | AU7: 6870 | AV7: 0 | AW7: 0 | AX7: 0 | AY7: 0 | AZ7: 0 | BA7: 6870 | BB7: 0 | BC7: 0 | BD7: 0 | BE7: 57 | BF7: 0 | BG7: 0 | BH7: 0 | BI7: 0 | BJ7: 0 | BK7: 57 | BL7: 0 | BM7: 0 | BN7: 0
A8: 00173069600 | B8: ADVAIR DISKUS 250-50MCG/DOSE AEROSOL 60EA | C8: 60 | D8: 3 | E8: 3 | F8: 190 | G8: 180 | H8: 0 | I8: 180 | J8: 0 | K8: 0 | L8: 0 | M8: 0 | N8: 0 | O8: 0 | P8: 0 | Q8: 3 | R8: 0 | S8: 3 | T8: 0 | U8: 0 | V8: 0 | W8: 0 | X8: 0 | Y8: 0 | Z8: 0 | AA8: 0 | AB8: 3 | AC8: 0 | AD8: 3 | AE8: 3 | AF8: 3 | AG8: 3 | AH8: 3 | AI8: 3 | AJ8: 3 | AK8: 535 | AL8: 0 | AM8: 535 | AN8: 0 | AO8: 0 | AP8: 0 | AQ8: 0 | AR8: 0 | AS8: 0 | AT8: 0 | AU8: 570 | AV8: 0 | AW8: 570 | AX8: 0 | AY8: 0 | AZ8: 0 | BA8: 0 | BB8: 0 | BC8: 0 | BD8: 0 | BE8: -35 | BF8: 0 | BG8: -35 | BH8: 0 | BI8: 0 | BJ8: 0 | BK8: 0 | BL8: 0 | BM8: 0 | BN8: 0
A9: 00173071720 | B9: ADVAIR HFA 230-21 MCG/ACT INHALATION AEROSOL | C9: 12 | D9: 3 | E9: 3 | F9: 428 | G9: 36 | H9: 0 | I9: 0 | J9: 0 | K9: 0 | L9: 0 | M9: 36 | N9: 0 | O9: 0 | P9: 0 | Q9: 3 | R9: 0 | S9: 0 | T9: 0 | U9: 0 | V9: 0 | W9: 3 | X9: 0 | Y9: 0 | Z9: 0 | AA9: 0 | AB9: 3 | AC9: 3 | AD9: 3 | AE9: 3 | AF9: 3 | AG9: 0 | AH9: 3 | AI9: 3 | AJ9: 3 | AK9: 1293 | AL9: 0 | AM9: 0 | AN9: 0 | AO9: 0 | AP9: 0 | AQ9: 1293 | AR9: 0 | AS9: 0 | AT9: 0 | AU9: 1284 | AV9: 0 | AW9: 0 | AX9: 0 | AY9: 0 | AZ9: 0 | BA9: 1284 | BB9: 0 | BC9: 0 | BD9: 0 | BE9: 9 | BF9: 0 | BG9: 0 | BH9: 0 | BI9: 0 | BJ9: 0 | BK9: 9 | BL9: 0 | BM9: 0 | BN9: 0
A10: 33332002503 | B10: AFLURIA PRESERVATIVE FREE 0.5 ML INTRAMUSCULAR SUSPENSION PREFILLED SYRINGE | C10: 5 | D10: 0 | E10: 0 | F10: 0 | G10: 1.5 | H10: 0 | I10: 1.5 | J10: 0 | K10: 0 | L10: 0 | M10: 0 | N10: 0 | O10: 0 | P10: 0 | Q10: 0.3 | R10: 0 | S10: 0.3 | T10: 0 | U10: 0 | V10: 0 | W10: 0 | X10: 0 | Y10: 0 | Z10: 0 | AA10: -0.3 | AB10: 0 | AC10: -0.3 | AD10: 0 | AE10: 0 | AF10: 0 | AG10: 0 | AH10: 0 | AI10: 0 | AJ10: 0 | AK10: 63 | AL10: 0 | AM10: 63 | AN10: 0 | AO10: 0 | AP10: 0 | AQ10: 0 | AR10: 0 | AS10: 0 | AT10: 0 | AU10: 0 | AV10: 0 | AW10: 0 | AX10: 0 | AY10: 0 | AZ10: 0 | BA10: 0 | BB10: 0 | BC10: 0 | BD10: 0 | BE10: 63 | BF10: 0 | BG10: 63 | BH10: 0 | BI10: 0 | BJ10: 0 | BK10: 0 | BL10: 0 | BM10: 0 | BN10: 0
A11: 00310908012 | B11: AIRSUPRA 90-80 MCG/ACT INHALATION AEROSOL | C11: 10.7 | D11: 4 | E11: 4 | F11: 490 | G11: 74.9 | H11: 0 | I11: 32.1 | J11: 10.7 | K11: 0 | L11: 0 | M11: 32.1 | N11: 0 | O11: 0 | P11: 0 | Q11: 7 | R11: 0 | S11: 3 | T11: 1 | U11: 0 | V11: 0 | W11: 3 | X11: 0 | Y11: 0 | Z11: 0 | AA11: -3 | AB11: 4 | AC11: 1 | AD11: 3 | AE11: 4 | AF11: 4 | AG11: 1 | AH11: 4 | AI11: 4 | AJ11: 4 | AK11: 3357 | AL11: 0 | AM11: 1428 | AN11: 437 | AO11: 0 | AP11: 0 | AQ11: 1452 | AR11: 0 | AS11: 0 | AT11: 0 | AU11: 3430 | AV11: 0 | AW11: 1470 | AX11: 490 | AY11: 0 | AZ11: 0 | BA11: 1470 | BB11: 0 | BC11: 0 | BD11: 0 | BE11: -73 | BF11: 0 | BG11: -42 | BH11: -53 | BI11: 0 | BJ11: 0 | BK11: -18 | BL11: 0 | BM11: 0 | BN11: 0
A12: 00023917715 | B12: ALPHAGAN P 0.15 % OPHTHALMIC SOLUTION | C12: 15 | D12: 0 | E12: 0 | F12: 0 | G12: 15 | H12: 0 | I12: 0 | J12: 0 | K12: 0 | L12: 0 | M12: 15 | N12: 0 | O12: 0 | P12: 0 | Q12: 1 | R12: 0 | S12: 0 | T12: 0 | U12: 0 | V12: 0 | W12: 1 | X12: 0 | Y12: 0 | Z12: 0 | AA12: -1 | AB12: 0 | AC12: 0 | AD12: 0 | AE12: 0 | AF12: 0 | AG12: -1 | AH12: 0 | AI12: 0 | AJ12: 0 | AK12: 608 | AL12: 0 | AM12: 0 | AN12: 0 | AO12: 0 | AP12: 0 | AQ12: 608 | AR12: 0 | AS12: 0 | AT12: 0 | AU12: 0 | AV12: 0 | AW12: 0 | AX12: 0 | AY12: 0 | AZ12: 0 | BA12: 0 | BB12: 0 | BC12: 0 | BD12: 0 | BE12: 608 | BF12: 0 | BG12: 0 | BH12: 0 | BI12: 0 | BJ12: 0 | BK12: 608 | BL12: 0 | BM12: 0 | BN12: 0
A13: 00173086910 | B13: ANORO ELLIPTA 62.5-25MCG/INH AEROSOL 60EA | C13: 60 | D13: 3 | E13: 3 | F13: 471 | G13: 120 | H13: 0 | I13: 120 | J13: 0 | K13: 0 | L13: 0 | M13: 0 | N13: 0 | O13: 0 | P13: 0 | Q13: 2 | R13: 0 | S13: 2 | T13: 0 | U13: 0 | V13: 0 | W13: 0 | X13: 0 | Y13: 0 | Z13: 0 | AA13: 1 | AB13: 3 | AC13: 1 | AD13: 3 | AE13: 3 | AF13: 3 | AG13: 3 | AH13: 3 | AI13: 3 | AJ13: 3 | AK13: 930 | AL13: 0 | AM13: 930 | AN13: 0 | AO13: 0 | AP13: 0 | AQ13: 0 | AR13: 0 | AS13: 0 | AT13: 0 | AU13: 942 | AV13: 0 | AW13: 942 | AX13: 0 | AY13: 0 | AZ13: 0 | BA13: 0 | BB13: 0 | BC13: 0 | BD13: 0 | BE13: -12 | BF13: 0 | BG13: -12 | BH13: 0 | BI13: 0 | BJ13: 0 | BK13: 0 | BL13: 0 | BM13: 0 | BN13: 0
A14: 58160084811 | B14: AREXVY 120 MCG/0.5ML INTRAMUSCULAR SUSPENSION RECONSTITUTED | C14: 10 | D14: 1 | E14: 1 | F14: 2949 | G14: 2 | H14: 0 | I14: 2 | J14: 0 | K14: 0 | L14: 0 | M14: 0 | N14: 0 | O14: 0 | P14: 0 | Q14: 0.2 | R14: 0 | S14: 0.2 | T14: 0 | U14: 0 | V14: 0 | W14: 0 | X14: 0 | Y14: 0 | Z14: 0 | AA14: 0.8 | AB14: 1 | AC14: 0.8 | AD14: 1 | AE14: 1 | AF14: 1 | AG14: 1 | AH14: 1 | AI14: 1 | AJ14: 1 | AK14: 595 | AL14: 0 | AM14: 595 | AN14: 0 | AO14: 0 | AP14: 0 | AQ14: 0 | AR14: 0 | AS14: 0 | AT14: 0 | AU14: 590 | AV14: 0 | AW14: 590 | AX14: 0 | AY14: 0 | AZ14: 0 | BA14: 0 | BB14: 0 | BC14: 0 | BD14: 0 | BE14: 5 | BF14: 0 | BG14: 5 | BH14: 0 | BI14: 0 | BJ14: 0 | BK14: 0 | BL14: 0 | BM14: 0 | BN14: 0
A15: 00173087410 | B15: ARNUITY ELLIPTA 100 MCG/ACT INH AEROSOL | C15: 30 | D15: 2 | E15: 2 | F15: 203 | G15: 90 | H15: 0 | I15: 90 | J15: 0 | K15: 0 | L15: 0 | M15: 0 | N15: 0 | O15: 0 | P15: 0 | Q15: 3 | R15: 0 | S15: 3 | T15: 0 | U15: 0 | V15: 0 | W15: 0 | X15: 0 | Y15: 0 | Z15: 0 | AA15: -1 | AB15: 2 | AC15: -1 | AD15: 2 | AE15: 2 | AF15: 2 | AG15: 2 | AH15: 2 | AI15: 2 | AJ15: 2 | AK15: 585 | AL15: 0 | AM15: 584 | AN15: 0 | AO15: 0 | AP15: 0 | AQ15: 0 | AR15: 0 | AS15: 0 | AT15: 0 | AU15: 609 | AV15: 0 | AW15: 609 | AX15: 0 | AY15: 0 | AZ15: 0 | BA15: 0 | BB15: 0 | BC15: 0 | BD15: 0 | BE15: -24 | BF15: 0 | BG15: -26 | BH15: 0 | BI15: 0 | BJ15: 0 | BK15: 0 | BL15: 0 | BM15: 0 | BN15: 0
... A208: 69557011130 | B208: ZTLIDO 1.8 % EXTERNAL PATCH | C208: 30 | D208: 4 | E208: 4 | F208: 372 | G208: 180 | H208: 0 | I208: 180 | J208: 0 | K208: 0 | L208: 0 | M208: 0 | N208: 0 | O208: 0 | P208: 0 | Q208: 6 | R208: 0 | S208: 6 | T208: 0 | U208: 0 | V208: 0 | W208: 0 | X208: 0 | Y208: 0 | Z208: 0 | AA208: -2 | AB208: 4 | AC208: -2 | AD208: 4 | AE208: 4 | AF208: 4 | AG208: 4 | AH208: 4 | AI208: 4 | AJ208: 4 | AK208: 2144 | AL208: 0 | AM208: 2126 | AN208: 0 | AO208: 0 | AP208: 0 | AQ208: 0 | AR208: 0 | AS208: 0 | AT208: 0 | AU208: 2232 | AV208: 0 | AW208: 2232 | AX208: 0 | AY208: 0 | AZ208: 0 | BA208: 0 | BB208: 0 | BC208: 0 | BD208: 0 | BE208: -88 | BF208: 0 | BG208: -106 | BH208: 0 | BI208: 0 | BJ208: 0 | BK208: 0 | BL208: 0 | BM208: 0 | BN208: 0
A209: Totals | AK209: =SUM(AK4:AK208) | AL209: =SUM(AL4:AL208) | AM209: =SUM(AM4:AM208) | AN209: =SUM(AN4:AN208) | AO209: =SUM(AO4:AO208) | AP209: =SUM(AP4:AP208) | AQ209: =SUM(AQ4:AQ208) | AR209: =SUM(AR4:AR208) | ... BN209: =SUM(BN4:BN208)

Sheet BIN to Processor
A1: BIN Numbers Billed (from Custom Log) | F1: Unmapped BIN Numbers (000000)
A2: BIN | B2: Processor | C2: Total Rx | F2: BIN | G2: RX # | H2: Fill Date
A3: 015581 | B3: ARG/HUM | C3: 1 | F3: 000000 | G3: 121328 | H3: 2026-01-05
A4: 015599 | B4: ARG/HUM | C4: 2 | F4: 000000 | G4: 109069 | H4: 2026-01-06
A5: 004336 | B5: CAREMARK | C5: 1101 | F5: 000000 | G5: 139433 | H5: 2026-01-16
A6: 013089 | B6: CAREMARK | C6: 1 | F6: 000000 | G6: 115458 | H6: 2026-01-21
A7: 020099 | B7: CAREMARK | C7: 10 | F7: 000000 | G7: 121328 | H7: 2026-01-30
A8: 020107 | B8: CAREMARK | C8: 4 | F8: 000000 | G8: 139433 | H8: 2026-02-13
A9: 020115 | B9: CAREMARK | C9: 8 | F9: 000000 | G9: 143448 | H9: 2026-02-16
A10: 610502 | B10: CAREMARK | C10: 52 | F10: 000000 | G10: 121328 | H10: 2026-02-24
A11: 003858 | B11: EXPRESS | C11: 25
A12: 017010 | B12: EXPRESS | C12: 24
A13: 400023 | B13: EXPRESS | C13: 3
A14: 610014 | B14: EXPRESS | C14: 101
A15: 007895 | B15: FDS | C15: 4
A16: 015574 | B16: MEDIMP | C16: 94
A17: 004740 | B17: NYM | C17: 375
A18: 610011 | B18: OPTUM | C18: 16
A19: 610097 | B19: OPTUM | C19: 29
A20: 610279 | B20: OPTUM | C20: 5
A21: 610494 | B21: OPTUM | C21: 5
A22: 610455 | B22: PRIMECAPRX | C22: 4
... A24: 000000 | B24: Unmapped | C24: 8
B25: Grand Total | C25: =SUM(C3:C24)

Sheet Needs to be ordered - All
A1: Hil (hh) - Need to Order - ALL
A2: NDC # | B2: Drug Name | C2: Pkg Size | D2: ARG/HUM_D | E2: CAREMARK_D | F2: EXPRESS_D | G2: FDS_D | H2: MEDIMP_D | I2: NYM_D | J2: OPTUM_D | K2: PRIMECAPRX_D | L2: RELAYHLTH_D | M2: To Order | N2: Paper Work | O2: PRICE | P2: Total Order Price | Q2: Insurance-wise Order Estimate ($) | R2: Amount
A3: 59148000713 | B3: ABILIFY 5MG TABLET | C3: 30 | D3: 2 | E3: 2 | F3: 2 | G3: 2 | H3: 2 | I3: -2 | J3: 2 | K3: 2 | L3: 2 | M3: 2 | O3: 563 | P3: 1126 | Q3: ARG/HUM_D | R3: =SUMPRODUCT((-D3:D101)*(D3:D101<0),O3:O101)
A4: 33332002503 | B4: AFLURIA PRESERVATIVE FREE 0.5 ML INTRAMUSCULAR SUSPENSION PREFILLED SYRINGE | C4: 5 | D4: 0 | E4: -0.3 | F4: 0 | G4: 0 | H4: 0 | I4: 0 | J4: 0 | K4: 0 | L4: 0 | M4: 0.3 | O4: 0 | P4: 0 | Q4: CAREMARK_D | R4: =SUMPRODUCT((-E3:E101)*(E3:E101<0),O3:O101)
A5: 00023917715 | B5: ALPHAGAN P 0.15 % OPHTHALMIC SOLUTION | C5: 15 | D5: 0 | E5: 0 | F5: 0 | G5: 0 | H5: 0 | I5: -1 | J5: 0 | K5: 0 | L5: 0 | M5: 1 | O5: 0 | P5: 0 | Q5: EXPRESS_D | R5: =SUMPRODUCT((-F3:F101)*(F3:F101<0),O3:O101)
A6: 00173087410 | B6: ARNUITY ELLIPTA 100 MCG/ACT INH AEROSOL | C6: 30 | D6: 2 | E6: -1 | F6: 2 | G6: 2 | H6: 2 | I6: 2 | J6: 2 | K6: 2 | L6: 2 | M6: 1 | O6: 203 | P6: 203 | Q6: FDS_D | R6: =SUMPRODUCT((-G3:G101)*(G3:G101<0),O3:O101)
A7: 00173088810 | B7: ARNUITY ELLIPTA 50 MCG/ACT INHAEROSOL | C7: 30 | D7: 0 | E7: 0 | F7: 0 | G7: 0 | H7: 0 | I7: -1 | J7: 0 | K7: 0 | L7: 0 | M7: 1 | O7: 0 | P7: 0 | Q7: MEDIMP_D | R7: =SUMPRODUCT((-H3:H101)*(H3:H101<0),O3:O101)
A8: 00173085910 | B8: BREO ELLIPTA 100-25 MCG/ACT INH AEROSOL | C8: 60 | D8: 8 | E8: -4 | F8: 8 | G8: 9 | H8: 9 | I8: 9 | J8: 9 | K8: 9 | L8: 9 | M8: 4 | O8: 393 | P8: 1572 | Q8: NYM_D | R8: =SUMPRODUCT((-I3:I101)*(I3:I101<0),O3:O101)
A9: 00310737220 | B9: BUDESONIDE-FORMOTEROL FUMARATE 80-4.5MCG/ACT AEROSOL | C9: 10.2 | D9: 9 | E9: -9 | F9: 6 | G9: 9 | H9: 6 | I9: 9 | J9: 9 | K9: 9 | L9: 9 | M9: 9 | O9: 139 | P9: 1251 | Q9: OPTUM_D | R9: =SUMPRODUCT((-J3:J101)*(J3:J101<0),O3:O101)
A10: 00310737020 | B10: BUDESONIDE/FORMOTEROL 160 /4.5 MCG (SYMBICORT) | C10: 10.2 | D10: 19 | E10: -3 | F10: 11 | G10: 19 | H10: 16 | I10: 19 | J10: 19 | K10: 19 | L10: 19 | M10: 3 | O10: 180 | P10: 540 | Q10: PRIMECAPRX_D | R10: =SUMPRODUCT((-K3:K101)*(K3:K101<0),O3:O101)
A11: 47335050696 | B11: CEQUA 0.09% SOLUTION | C11: 60 | D11: 5 | E11: -1 | F11: 5 | G11: 5 | H11: 5 | I11: 5 | J11: 5 | K11: 5 | L11: 5 | M11: 1 | O11: 633 | P11: 633 | Q11: RELAYHLTH_D | R11: =SUMPRODUCT((-L3:L101)*(L3:L101<0),O3:O101)
A12: 68382052960 | B12: CHOLESTYRAMINE LIGHT 4GM PACK | C12: 60 | D12: 0 | E12: -1 | F12: 0 | G12: 0 | H12: 0 | I12: 0 | J12: 0 | K12: 0 | L12: 0 | M12: 1 | O12: 0 | P12: 0
A13: 00023921110 | B13: COMBIGAN 0.2-0.5% OPTH SOLUTION 10ML | C13: 10 | D13: 0 | E13: -4 | F13: 0 | G13: 0 | H13: 0 | I13: 0 | J13: 0 | K13: 0 | L13: 0 | M13: 4 | O13: 0 | P13: 0
A14: 00023921115 | B14: COMBIGAN 0.2-0.5% OPTH SOLUTION 15ML | C14: 15 | D14: 0 | E14: -6 | F14: 0 | G14: 0 | H14: 0 | I14: 0 | J14: 0 | K14: 0 | L14: 0 | M14: 6 | O14: 0 | P14: 0
A15: 00193730850 | B15: CONTOUR NEXT STRIP DME | C15: 50 | D15: 0 | E15: 0 | F15: 0 | G15: -2 | H15: 0 | I15: 0 | J15: 0 | K15: 0 | L15: 0 | M15: 2 | O15: 0 | P15: 0
A16: 00193731150 | B16: CONTOUR NEXT TEST STRIPS | C16: 50 | D16: 0 | E16: -313 | F16: 0 | G16: -6 | H16: -28 | I16: -60 | J16: -12 | K16: 0 | L16: 0 | M16: 313 | O16: 0 | P16: 0
A17: 00032004670 | B17: CREON 6000-19000 UNIT ORAL CAPSULE DELAYED RELEASE PARTICLES | C17: 100 | D17: 0 | E17: -1.8 | F17: 0 | G17: 0 | H17: 0 | I17: 0 | J17: 0 | K17: 0 | L17: 0 | M17: 1.8 | O17: 0 | P17: 0
A18: 42023011101 | B18: DELESTROGEN 20 MG/ML INTRAMUSCULAR OIL | C18: 5 | D18: 0 | E18: 0 | F18: 0 | G18: 0 | H18: 0 | I18: -1 | J18: 0 | K18: 0 | L18: 0 | M18: 1 | O18: 0 | P18: 0
A19: 64764017530 | B19: DEXILANT 60MG CAP | C19: 30 | D19: 1 | E19: -2 | F19: 1 | G19: 1 | H19: 1 | I19: 1 | J19: 1 | K19: 1 | L19: 1 | M19: 2 | O19: 297 | P19: 594
A20: 78206012601 | B20: DULERA 200-5 MCG/ACT INH AEROSOL 13GM | C20: 13 | D20: 2 | E20: 2 | F20: 2 | G20: 2 | H20: 2 | I20: -1 | J20: 2 | K20: 2 | L20: 2 | M20: 1 | O20: 331 | P20: 331
A21: 00003089421 | B21: ELIQUIS 5MG TAB | C21: 60 | D21: 83 | E21: -5 | F21: 76 | G21: 83 | H21: 76 | I21: 74 | J21: 83 | K21: 83 | L21: 83 | M21: 5 | O21: 336 | P21: 1680
A22: 73302045601 | B22: ELLA 30 MG ORAL TABLET | C22: 1 | D22: 0 | E22: 0 | F22: 0 | G22: 0 | H22: 0 | I22: 0 | J22: -1 | K22: 0 | L22: 0 | M22: 1 | O22: 0 | P22: 0
A23: 49502010102 | B23: EPINEPHRINE (JR) 0.15MG/0.3ML INJECTION 2ML | C23: 2 | D23: 0 | E23: 0 | F23: 0 | G23: 0 | H23: 0 | I23: -2 | J23: 0 | K23: 0 | L23: 0 | M23: 2 | O23: 0 | P23: 0
... A101: 69557011130 | B101: ZTLIDO 1.8 % EXTERNAL PATCH | C101: 30 | D101: 4 | E101: -2 | F101: 4 | G101: 4 | H101: 4 | I101: 4 | J101: 4 | K101: 4 | L101: 4 | M101: 2 | O101: 372 | P101: 744
O103: Grand Total | P103: =SUBTOTAL(109,P3:P101)

Sheet Do Not Order - ALL
A1: Hil (hh) - Do Not Order
A2: NDC # | B2: Drug Name | C2: Pkg Size | D2: ARG/HUM_D | E2: CAREMARK_D | F2: EXPRESS_D | G2: FDS_D | H2: MEDIMP_D | I2: NYM_D | J2: OPTUM_D | K2: PRIMECAPRX_D | L2: RELAYHLTH_D | M2: Do Not Order | N2: Paper Work
A3: 65702072910 | B3: ACCU-CHEK GUIDE W/DEVICE KIT | C3: 1 | D3: 3 | E3: 3 | F3: 2 | G3: 3 | H3: 3 | I3: 3 | J3: 3 | K3: 3 | L3: 3 | M3: 2
A4: 00310908012 | B4: AIRSUPRA 90-80 MCG/ACT INHALATION AEROSOL | C4: 10.7 | D4: 4 | E4: 1 | F4: 3 | G4: 4 | H4: 4 | I4: 1 | J4: 4 | K4: 4 | L4: 4 | M4: 1
A5: 00173086910 | B5: ANORO ELLIPTA 62.5-25MCG/INH AEROSOL 60EA | C5: 60 | D5: 3 | E5: 1 | F5: 3 | G5: 3 | H5: 3 | I5: 3 | J5: 3 | K5: 3 | L5: 3 | M5: 1
A6: 58160084811 | B6: AREXVY 120 MCG/0.5ML INTRAMUSCULAR SUSPENSION RECONSTITUTED | C6: 10 | D6: 1 | E6: 0.8 | F6: 1 | G6: 1 | H6: 1 | I6: 1 | J6: 1 | K6: 1 | L6: 1 | M6: 0.8
A7: 00002771559 | B7: BASAGLAR KWIKPEN 100UNIT/ML INJECTION | C7: 15 | D7: 45 | E7: 9.4 | F7: 43.2 | G7: 45 | H7: 45 | I7: 43.8 | J7: 45 | K7: 45 | L7: 45 | M7: 9.4
A8: 61958250101 | B8: BIKTARVY 50-200-25MG TABLET | C8: 30 | D8: 7 | E8: 7 | F8: 6 | G8: 7 | H8: 5 | I8: 3 | J8: 7 | K8: 7 | L8: 4 | M8: 3
A9: 00173088210 | B9: BREO ELLIPTA 200-25MCG/INH AEROSOL 60EA | C9: 60 | D9: 10 | E9: 8 | F9: 10 | G9: 10 | H9: 10 | I9: 10 | J9: 10 | K9: 10 | L9: 10 | M9: 8
A10: 00310461612 | B10: BREZTRI AEROSPHERE 160-9-4.8 MCG/ACT INHALATION AEROSOL | C10: 10.7 | D10: 8 | E10: 1 | F10: 5 | G10: 8 | H10: 7 | I10: 5 | J10: 5 | K10: 8 | L10: 8 | M10: 1
A11: 00032263601 | B11: CREON 24000-76000 UNIT CAPSULE DR | C11: 100 | D11: 3 | E11: 0.3 | F11: 3 | G11: 3 | H11: 3 | I11: 3 | J11: 3 | K11: 3 | L11: 3 | M11: 0.3
A12: 00032301613 | B12: CREON 36000UNIT CAPSULE | C12: 100 | D12: 3 | E12: 0.3 | F12: 3 | G12: 3 | H12: 3 | I12: 3 | J12: 3 | K12: 3 | L12: 3 | M12: 0.3
A13: 00074732713 | B13: DEPAKOTE 500MG TABLET DELAYED RELEASE | C13: 100 | D13: 2 | E13: 2 | F13: 2 | G13: 2 | H13: 2 | I13: 0.2 | J13: 2 | K13: 2 | L13: 2 | M13: 0.2
A14: 00074740113 | B14: DEPAKOTE ER 250 MG TABLET | C14: 100 | D14: 2 | E14: 2 | F14: 2 | G14: 2 | H14: 2 | I14: 1.1 | J14: 2 | K14: 2 | L14: 2 | M14: 1.1
... A57: 00002248480 | B57: ZEPBOUND 7.5 MG/0.5ML AUTO-INJECTOR | C57: 2 | D57: 2 | E57: 1 | F57: 2 | G57: 2 | H57: 2 | I57: 2 | J57: 1 | K57: 2 | L57: 2 | M57: 1

Sheet Never Ordered - Check
A1: Hil (hh) - Never Ordered Package - Check
A2: Drug Name | B2: NDC # | C2: Pkg Size | D2: Total Purchased | E2: ALL_PBM_P
A3: AFLURIA PRESERVATIVE FREE 0.5 ML INTRAMUSCULAR SUSPENSION PREFILLED SYRINGE | B3: 33332002503 | C3: 5 | D3: 0 | E3: 0.3
A4: ALPHAGAN P 0.15 % OPHTHALMIC SOLUTION | B4: 00023917715 | C4: 15 | D4: 0 | E4: 1
A5: ARNUITY ELLIPTA 50 MCG/ACT INHAEROSOL | B5: 00173088810 | C5: 30 | D5: 0 | E5: 1
A6: CHOLESTYRAMINE LIGHT 4GM PACK | B6: 68382052960 | C6: 60 | D6: 0 | E6: 1
A7: COMBIGAN 0.2-0.5% OPTH SOLUTION 10ML | B7: 00023921110 | C7: 10 | D7: 0 | E7: 4
A8: COMBIGAN 0.2-0.5% OPTH SOLUTION 15ML | B8: 00023921115 | C8: 15 | D8: 0 | E8: 6
A9: CONTOUR NEXT STRIP DME | B9: 00193730850 | C9: 50 | D9: 0 | E9: 2
A10: CONTOUR NEXT TEST STRIPS | B10: 00193731150 | C10: 50 | D10: 0 | E10: 431
A11: CREON 6000-19000 UNIT ORAL CAPSULE DELAYED RELEASE PARTICLES | B11: 00032004670 | C11: 100 | D11: 0 | E11: 1.8
A12: DELESTROGEN 20 MG/ML INTRAMUSCULAR OIL | B12: 42023011101 | C12: 5 | D12: 0 | E12: 1
A13: ELLA 30 MG ORAL TABLET | B13: 73302045601 | C13: 1 | D13: 0 | E13: 1
A14: EPINEPHRINE (JR) 0.15MG/0.3ML INJECTION 2ML | B14: 49502010102 | C14: 2 | D14: 0 | E14: 2
... A46: ZORYVE 0.3 % EXTERNAL FOAM | B46: 80610043060 | C46: 60 | D46: 0 | E46: 4

Sheet RX Comparison - All
A1: RX Comparision Analysis (All RXs)
A2: RX | B2: Fill Date | C2: NDC | D2: Drug Name | E2: Pkg Size | F2: Qty Filled | G2: Package Billed | H2: Kinray Final Price | I2: Ins Paid | J2: SDRA Amt | K2: COPAY | L2: Total = (Ins Paid + SDRA + COPAY) | M2: Difference | N2: BIN | O2: Processor | P2: PCN | Q2: Group
A3: 133477 | B3: 46049 | C3: 59148000713 | D3: ABILIFY 5MG TABLET | E3: 30 | F3: 30 | G3: 1 | H3: 563 | I3: 570.77 | J3: 0 | K3: 0 | L3: 570.77 | M3: 7.77 | N3: 004740 | O3: NYM | P3: 9314DA31
A4: 133477 | B4: 45994 | C4: 59148000713 | D4: ABILIFY 5MG TABLET | E4: 30 | F4: 30 | G4: 1 | H4: 562 | I4: 568.37 | J4: 0 | K4: 0 | L4: 568.37 | M4: 6.37 | N4: 004740 | O4: NYM | P4: 9314DA31
A5: 133477 | B5: 46021 | C5: 59148000713 | D5: ABILIFY 5MG TABLET | E5: 30 | F5: 30 | G5: 1 | H5: 562 | I5: 568.37 | J5: 0 | K5: 0 | L5: 568.37 | M5: 6.37 | N5: 004740 | O5: NYM | P5: 9314DA31
A6: 144533 | B6: 46077 | C6: 59148000713 | D6: ABILIFY 5MG TABLET | E6: 30 | F6: 30 | G6: 1 | H6: 563 | I6: 570.77 | J6: 0 | K6: 0 | L6: 570.77 | M6: 7.77 | N6: 004740 | O6: NYM | P6: 9314DA31
A7: 124727 | B7: 46009 | C7: 65702071110 | D7: ACCU-CHEK GUIDE IN VITRO STRIP | E7: 50 | F7: 100 | G7: 2 | H7: 40 | I7: 37.37 | J7: 0 | K7: 0 | L7: 37.37 | M7: -2.63 | N7: 004336 | O7: CAREMARK | P7: ADV | Q7: RX23MD
A8: 124196 | B8: 46062 | C8: 65702071110 | D8: ACCU-CHEK GUIDE IN VITRO STRIP | E8: 50 | F8: 100 | G8: 2 | H8: 40 | I8: 35.38 | J8: 0 | K8: 0 | L8: 35.38 | M8: -4.62 | N8: 610014 | O8: EXPRESS | P8: MEDDPRIME | Q8: 2FFA
A9: 123286 | B9: 46077 | C9: 65702071110 | D9: ACCU-CHEK GUIDE IN VITRO STRIP | E9: 50 | F9: 100 | G9: 2 | H9: 40 | I9: 28.61 | J9: 0 | K9: 7.15 | L9: 35.76 | M9: -4.24 | N9: 610014 | O9: EXPRESS | P9: MEDDPRIME | Q9: 2FFA
A10: 134364 | B10: 46028 | C10: 65702071110 | D10: ACCU-CHEK GUIDE IN VITRO STRIP | E10: 50 | F10: 100 | G10: 2 | H10: 40 | I10: 39.07 | J10: 0 | K10: 0 | L10: 39.07 | M10: -0.93 | N10: 610502 | O10: CAREMARK | P10: MEDDAET | Q10: RXAETD
A11: 142639 | B11: 46063 | C11: 65702071110 | D11: ACCU-CHEK GUIDE IN VITRO STRIP | E11: 50 | F11: 100 | G11: 2 | H11: 40 | I11: 28.61 | J11: 0 | K11: 7.15 | L11: 35.76 | M11: -4.24 | N11: 610014 | O11: EXPRESS | P11: MEDDPRIME | Q11: 2FFA
A12: 107242 | B12: 46062 | C12: 65702071110 | D12: ACCU-CHEK GUIDE IN VITRO STRIP | E12: 50 | F12: 100 | G12: 2 | H12: 40 | I12: 39.07 | J12: 0 | K12: 0 | L12: 39.07 | M12: -0.93 | N12: 610502 | O12: CAREMARK | P12: MEDDAET | Q12: RXAETD
A13: 123286 | B13: 46030 | C13: 65702071110 | D13: ACCU-CHEK GUIDE IN VITRO STRIP | E13: 50 | F13: 100 | G13: 2 | H13: 40 | I13: 28.61 | J13: 0 | K13: 7.15 | L13: 35.76 | M13: -4.24 | N13: 610014 | O13: EXPRESS | P13: MEDDPRIME | Q13: 2FFA
A14: 130956 | B14: 46060 | C14: 65702071110 | D14: ACCU-CHEK GUIDE IN VITRO STRIP | E14: 50 | F14: 200 | G14: 4 | H14: 80 | I14: 71.52 | J14: 0 | K14: 0 | L14: 71.52 | M14: -8.48 | N14: 610014 | O14: EXPRESS | P14: MEDDPRIME | Q14: 2FFA
A15: 139769 | B15: 46042 | C15: 65702071110 | D15: ACCU-CHEK GUIDE IN VITRO STRIP | E15: 50 | F15: 200 | G15: 4 | H15: 80 | I15: 71.52 | J15: 0 | K15: 0 | L15: 71.52 | M15: -8.48 | N15: 610014 | O15: EXPRESS | P15: MEDDPRIME | Q15: 2FFA
A16: 139610 | B16: 46041 | C16: 65702071110 | D16: ACCU-CHEK GUIDE IN VITRO STRIP | E16: 50 | F16: 100 | G16: 2 | H16: 40 | I16: 37.37 | J16: 0 | K16: 0 | L16: 37.37 | M16: -2.63 | N16: 004336 | O16: CAREMARK | P16: ADV | Q16: RX23MD
A17: 107242 | B17: 46034 | C17: 65702071110 | D17: ACCU-CHEK GUIDE IN VITRO STRIP | E17: 50 | F17: 100 | G17: 2 | H17: 40 | I17: 39.07 | J17: 0 | K17: 0 | L17: 39.07 | M17: -0.93 | N17: 610502 | O17: CAREMARK | P17: MEDDAET | Q17: RXAETD
A18: 124196 | B18: 46007 | C18: 65702071110 | D18: ACCU-CHEK GUIDE IN VITRO STRIP | E18: 50 | F18: 100 | G18: 2 | H18: 40 | I18: 35.76 | J18: 0 | K18: 0 | L18: 35.76 | M18: -4.24 | N18: 610014 | O18: EXPRESS | P18: MEDDPRIME | Q18: 2FFA
A19: 118726 | B19: 45992 | C19: 65702071110 | D19: ACCU-CHEK GUIDE IN VITRO STRIP | E19: 50 | F19: 100 | G19: 2 | H19: 40 | I19: 28.61 | J19: 0 | K19: 7.15 | L19: 35.76 | M19: -4.24 | N19: 610014 | O19: EXPRESS | P19: MEDDPRIME | Q19: 2FFA
A20: 123286 | B20: 46014 | C20: 65702071110 | D20: ACCU-CHEK GUIDE IN VITRO STRIP | E20: 50 | F20: 100 | G20: 2 | H20: 40 | I20: 40.85 | J20: 0 | K20: 0 | L20: 40.85 | M20: 0.85 | N20: 610097 | O20: OPTUM | P20: 9999
A21: 100762 | B21: 45992 | C21: 65702071110 | D21: ACCU-CHEK GUIDE IN VITRO STRIP | E21: 50 | F21: 200 | G21: 4 | H21: 80 | I21: 67.95 | J21: 0 | K21: 7.55 | L21: 75.5 | M21: -4.5 | N21: 015581 | O21: ARG/HUM | P21: 03200000 | Q21: Y9035
A22: 141797 | B22: 46057 | C22: 65702071110 | D22: ACCU-CHEK GUIDE IN VITRO STRIP | E22: 50 | F22: 100 | G22: 2 | H22: 40 | I22: 39.07 | J22: 0 | K22: 0 | L22: 39.07 | M22: -0.93 | N22: 610502 | O22: CAREMARK | P22: MEDDAET | Q22: RXAETD
A23: 110585 | B23: 46013 | C23: 65702071110 | D23: ACCU-CHEK GUIDE IN VITRO STRIP | E23: 50 | F23: 100 | G23: 2 | H23: 40 | I23: 15.51 | J23: 0 | K23: 29.99 | L23: 45.5 | M23: 5.5 | N23: 004336 | O23: CAREMARK | P23: ADV | Q23: RX7682
A24: 124196 | B24: 46035 | C24: 65702071110 | D24: ACCU-CHEK GUIDE IN VITRO STRIP | E24: 50 | F24: 100 | G24: 2 | H24: 40 | I24: 35.38 | J24: 0 | K24: 0 | L24: 35.38 | M24: -4.62 | N24: 610014 | O24: EXPRESS | P24: MEDDPRIME | Q24: 2FFA
A25: 143274 | B25: 46066 | C25: 65702072910 | D25: ACCU-CHEK GUIDE W/DEVICE KIT | E25: 1 | F25: 1 | G25: 1 | H25: 26 | I25: 21.18 | J25: 0 | K25: 0 | L25: 21.18 | M25: -4.82 | N25: 610014 | O25: EXPRESS | P25: MEDDPRIME | Q25: 2FFA
A26: 132679 | B26: 46036 | C26: 50242014301 | D26: ACTEMRA ACTPEN 162 MG/0.9ML SUBCUTANEOUS SOLUTION AUTO-INJECTOR | E26: 0.9 | F26: 1.8 | G26: 2 | H26: 2292 | I26: 2312.48 | J26: 0 | K26: 0 | L26: 2312.48 | M26: 20.48 | N26: 004740 | O26: NYM | P26: 9314DA31
A27: 132679 | B27: 46073 | C27: 50242014301 | D27: ACTEMRA ACTPEN 162 MG/0.9ML SUBCUTANEOUS SOLUTION AUTO-INJECTOR | E27: 0.9 | F27: 1.8 | G27: 2 | H27: 2290 | I27: 2312.48 | J27: 0 | K27: 0 | L27: 2312.48 | M27: 22.48 | N27: 004740 | O27: NYM | P27: 9314DA31
A28: 132679 | B28: 46010 | C28: 50242014301 | D28: ACTEMRA ACTPEN 162 MG/0.9ML SUBCUTANEOUS SOLUTION AUTO-INJECTOR | E28: 0.9 | F28: 1.8 | G28: 2 | H28: 2290 | I28: 2302.26 | J28: 0 | K28: 0 | L28: 2302.26 | M28: 12.26 | N28: 004740 | O28: NYM | P28: 9314DA31
A29: 141921 | B29: 46057 | C29: 00173069600 | D29: ADVAIR DISKUS 250-50MCG/DOSE AEROSOL 60EA | E29: 60 | F29: 180 | G29: 3 | H29: 570 | I29: 535.32 | J29: 0 | K29: 0 | L29: 535.32 | M29: -34.68 | N29: 004336 | O29: CAREMARK | P29: MEDDADV | Q29: RX8585
A30: 120744 | B30: 46007 | C30: 00173071720 | D30: ADVAIR HFA 230-21 MCG/ACT INHALATION AEROSOL | E30: 12 | F30: 12 | G30: 1 | H30: 424 | I30: 430.91 | J30: 0 | K30: 0 | L30: 430.91 | M30: 6.91 | N30: 004740 | O30: NYM | P30: 9314DA31
A31: 143441 | B31: 46069 | C31: 00173071720 | D31: ADVAIR HFA 230-21 MCG/ACT INHALATION AEROSOL | E31: 12 | F31: 12 | G31: 1 | H31: 428 | I31: 430.83 | J31: 0 | K31: 0 | L31: 430.83 | M31: 2.83 | N31: 004740 | O31: NYM | P31: 9314DA31
A32: 120744 | B32: 46034 | C32: 00173071720 | D32: ADVAIR HFA 230-21 MCG/ACT INHALATION AEROSOL | E32: 12 | F32: 12 | G32: 1 | H32: 424 | I32: 430.86 | J32: 0 | K32: 0 | L32: 430.86 | M32: 6.86 | N32: 004740 | O32: NYM | P32: 9314DA31
A33: 134992 | B33: 46003 | C33: 33332002503 | D33: AFLURIA PRESERVATIVE FREE 0.5 ML INTRAMUSCULAR SUSPENSION PREFILLED SYRINGE | E33: 5 | F33: 0.5 | G33: 0.1 | H33: 0 | I33: 20.79 | J33: 0 | K33: 0 | L33: 20.79 | M33: 0 | N33: 004336 | O33: CAREMARK | P33: MEDDADV | Q33: RX1110
A34: 138657 | B34: 46034 | C34: 33332002503 | D34: AFLURIA PRESERVATIVE FREE 0.5 ML INTRAMUSCULAR SUSPENSION PREFILLED SYRINGE | E34: 5 | F34: 0.5 | G34: 0.1 | H34: 0 | I34: 20.98 | J34: 0 | K34: 0 | L34: 20.98 | M34: 0 | N34: 004336 | O34: CAREMARK | P34: MEDDADV | Q34: RX1110
A35: 134597 | B35: 46001 | C35: 33332002503 | D35: AFLURIA PRESERVATIVE FREE 0.5 ML INTRAMUSCULAR SUSPENSION PREFILLED SYRINGE | E35: 5 | F35: 0.5 | G35: 0.1 | H35: 0 | I35: 20.79 | J35: 0 | K35: 0 | L35: 20.79 | M35: 0 | N35: 004336 | O35: CAREMARK | P35: MEDDADV | Q35: RX1110
A36: 142197 | B36: 46059 | C36: 00310908012 | D36: AIRSUPRA 90-80 MCG/ACT INHALATION AEROSOL | E36: 10.7 | F36: 10.7 | G36: 1 | H36: 490 | I36: 436.54 | J36: 0 | K36: 30 | L36: 466.54 | M36: -23.46 | N36: 610014 | O36: EXPRESS | Q36: LOCAL74
A37: 140593 | B37: 46049 | C37: 00310908012 | D37: AIRSUPRA 90-80 MCG/ACT INHALATION AEROSOL | E37: 10.7 | F37: 10.7 | G37: 1 | H37: 486 | I37: 479.3 | J37: 0 | K37: 0 | L37: 479.3 | M37: -6.7 | N37: 004336 | O37: CAREMARK | P37: MEDDADV | Q37: RX1110
A38: 130078 | B38: 45995 | C38: 00310908012 | D38: AIRSUPRA 90-80 MCG/ACT INHALATION AEROSOL | E38: 10.7 | F38: 10.7 | G38: 1 | H38: 486 | I38: 479.37 | J38: 0 | K38: 0 | L38: 479.37 | M38: -6.63 | N38: 004740 | O38: NYM | P38: 9314DA31
A39: 137179 | B39: 46024 | C39: 00310908012 | D39: AIRSUPRA 90-80 MCG/ACT INHALATION AEROSOL | E39: 10.7 | F39: 10.7 | G39: 1 | H39: 486 | I39: 479.45 | J39: 0 | K39: 0 | L39: 479.45 | M39: -6.55 | N39: 004740 | O39: NYM | P39: 9314DA31
A40: 138774 | B40: 46034 | C40: 00310908012 | D40: AIRSUPRA 90-80 MCG/ACT INHALATION AEROSOL | E40: 10.7 | F40: 10.7 | G40: 1 | H40: 486 | I40: 474.4 | J40: 0 | K40: 4.9 | L40: 479.3 | M40: -6.7 | N40: 004336 | O40: CAREMARK | P40: MEDDADV | Q40: RX1110
...

Sheet RX Comparison +ve
A1: RX Comparision +ve Analysis (All RXs)
A2: RX | B2: Fill Date | C2: NDC | D2: Drug Name | E2: Pkg Size | F2: Qty Filled | G2: Package Billed | H2: Kinray Final Price | I2: Ins Paid | J2: SDRA Amt | K2: COPAY | L2: Total = (Ins Paid + SDRA + COPAY) | M2: Difference | N2: BIN | O2: Processor | P2: PCN | Q2: Group
A3: 133477 | B3: 46021 | C3: 59148000713 | D3: ABILIFY 5MG TABLET | E3: 30 | F3: 30 | G3: 1 | H3: 562 | I3: 568.37 | J3: 0 | K3: 0 | L3: 568.37 | M3: 6.37 | N3: 004740 | O3: NYM | P3: 9314DA31
A4: 144533 | B4: 46077 | C4: 59148000713 | D4: ABILIFY 5MG TABLET | E4: 30 | F4: 30 | G4: 1 | H4: 563 | I4: 570.77 | J4: 0 | K4: 0 | L4: 570.77 | M4: 7.77 | N4: 004740 | O4: NYM | P4: 9314DA31
A5: 133477 | B5: 45994 | C5: 59148000713 | D5: ABILIFY 5MG TABLET | E5: 30 | F5: 30 | G5: 1 | H5: 562 | I5: 568.37 | J5: 0 | K5: 0 | L5: 568.37 | M5: 6.37 | N5: 004740 | O5: NYM | P5: 9314DA31
A6: 133477 | B6: 46049 | C6: 59148000713 | D6: ABILIFY 5MG TABLET | E6: 30 | F6: 30 | G6: 1 | H6: 563 | I6: 570.77 | J6: 0 | K6: 0 | L6: 570.77 | M6: 7.77 | N6: 004740 | O6: NYM | P6: 9314DA31
A7: 123286 | B7: 46014 | C7: 65702071110 | D7: ACCU-CHEK GUIDE IN VITRO STRIP | E7: 50 | F7: 100 | G7: 2 | H7: 40 | I7: 40.85 | J7: 0 | K7: 0 | L7: 40.85 | M7: 0.85 | N7: 610097 | O7: OPTUM | P7: 9999
A8: 110585 | B8: 46013 | C8: 65702071110 | D8: ACCU-CHEK GUIDE IN VITRO STRIP | E8: 50 | F8: 100 | G8: 2 | H8: 40 | I8: 15.51 | J8: 0 | K8: 29.99 | L8: 45.5 | M8: 5.5 | N8: 004336 | O8: CAREMARK | P8: ADV | Q8: RX7682
A9: 132679 | B9: 46073 | C9: 50242014301 | D9: ACTEMRA ACTPEN 162 MG/0.9ML SUBCUTANEOUS SOLUTION AUTO-INJECTOR | E9: 0.9 | F9: 1.8 | G9: 2 | H9: 2290 | I9: 2312.48 | J9: 0 | K9: 0 | L9: 2312.48 | M9: 22.48 | N9: 004740 | O9: NYM | P9: 9314DA31
A10: 132679 | B10: 46010 | C10: 50242014301 | D10: ACTEMRA ACTPEN 162 MG/0.9ML SUBCUTANEOUS SOLUTION AUTO-INJECTOR | E10: 0.9 | F10: 1.8 | G10: 2 | H10: 2290 | I10: 2302.26 | J10: 0 | K10: 0 | L10: 2302.26 | M10: 12.26 | N10: 004740 | O10: NYM | P10: 9314DA31
A11: 132679 | B11: 46036 | C11: 50242014301 | D11: ACTEMRA ACTPEN 162 MG/0.9ML SUBCUTANEOUS SOLUTION AUTO-INJECTOR | E11: 0.9 | F11: 1.8 | G11: 2 | H11: 2292 | I11: 2312.48 | J11: 0 | K11: 0 | L11: 2312.48 | M11: 20.48 | N11: 004740 | O11: NYM | P11: 9314DA31
A12: 120744 | B12: 46034 | C12: 00173071720 | D12: ADVAIR HFA 230-21 MCG/ACT INHALATION AEROSOL | E12: 12 | F12: 12 | G12: 1 | H12: 424 | I12: 430.86 | J12: 0 | K12: 0 | L12: 430.86 | M12: 6.86 | N12: 004740 | O12: NYM | P12: 9314DA31
A13: 120744 | B13: 46007 | C13: 00173071720 | D13: ADVAIR HFA 230-21 MCG/ACT INHALATION AEROSOL | E13: 12 | F13: 12 | G13: 1 | H13: 424 | I13: 430.91 | J13: 0 | K13: 0 | L13: 430.91 | M13: 6.91 | N13: 004740 | O13: NYM | P13: 9314DA31
A14: 143441 | B14: 46069 | C14: 00173071720 | D14: ADVAIR HFA 230-21 MCG/ACT INHALATION AEROSOL | E14: 12 | F14: 12 | G14: 1 | H14: 428 | I14: 430.83 | J14: 0 | K14: 0 | L14: 430.83 | M14: 2.83 | N14: 004740 | O14: NYM | P14: 9314DA31
A15: 143556 | B15: 46069 | C15: 00310908012 | D15: AIRSUPRA 90-80 MCG/ACT INHALATION AEROSOL | E15: 10.7 | F15: 10.7 | G15: 1 | H15: 490 | I15: 493.53 | J15: 0 | K15: 0 | L15: 493.53 | M15: 3.53 | N15: 004740 | O15: NYM | P15: 9314DA31
A16: 134877 | B16: 46003 | C16: 58160084811 | D16: AREXVY 120 MCG/0.5ML INTRAMUSCULAR SUSPENSION RECONSTITUTED | E16: 10 | F16: 1 | G16: 0.1 | H16: 294.9 | I16: 306.19 | J16: 0 | K16: 0 | L16: 306.19 | M16: 11.29 | N16: 004336 | O16: CAREMARK | P16: ADV | Q16: RX23MD
A17: 111641 | B17: 45996 | C17: 00002771559 | D17: BASAGLAR KWIKPEN 100UNIT/ML INJECTION | E17: 15 | F17: 9 | G17: 0.6 | H17: 188.4 | I17: 198.55 | J17: 0 | K17: 0 | L17: 198.55 | M17: 10.15 | N17: 004740 | O17: NYM | P17: 9314DA31
A18: 120446 | B18: 46039 | C18: 00002771559 | D18: BASAGLAR KWIKPEN 100UNIT/ML INJECTION | E18: 15 | F18: 3 | G18: 0.2 | H18: 63 | I18: 72.97 | J18: 0 | K18: 0 | L18: 72.97 | M18: 9.97 | N18: 004740 | O18: NYM | P18: 9314DA31
A19: 143642 | B19: 46070 | C19: 00002771559 | D19: BASAGLAR KWIKPEN 100UNIT/ML INJECTION | E19: 15 | F19: 3 | G19: 0.2 | H19: 63.4 | I19: 72.97 | J19: 0 | K19: 0 | L19: 72.97 | M19: 9.57 | N19: 004740 | O19: NYM | P19: 9314DA31
A20: 120446 | B20: 46013 | C20: 00002771559 | D20: BASAGLAR KWIKPEN 100UNIT/ML INJECTION | E20: 15 | F20: 3 | G20: 0.2 | H20: 62.8 | I20: 72.97 | J20: 0 | K20: 0 | L20: 72.97 | M20: 10.17 | N20: 004740 | O20: NYM | P20: 9314DA31
A21: 134334 | B21: 46000 | C21: 61958250101 | D21: BIKTARVY 50-200-25MG TABLET | E21: 30 | F21: 30 | G21: 1 | H21: 4111 | I21: 4202.74 | J21: 0 | K21: 0 | L21: 4202.74 | M21: 91.74 | N21: 610490 | O21: RELAYHLTH | P21: ADAP01
A22: 141611 | B22: 46056 | C22: 61958250101 | D22: BIKTARVY 50-200-25MG TABLET | E22: 30 | F22: 30 | G22: 1 | H22: 4111 | I22: 4202.74 | J22: 0 | K22: 0 | L22: 4202.74 | M22: 91.74 | N22: 610490 | O22: RELAYHLTH | P22: ADAP01
A23: 103554 | B23: 46045 | C23: 61958250101 | D23: BIKTARVY 50-200-25MG TABLET | E23: 30 | F23: 30 | G23: 1 | H23: 4111 | I23: 4111.27 | J23: 0 | K23: 0 | L23: 4111.27 | M23: 0.27 | N23: 004740 | O23: NYM | P23: 9314DA31
A24: 140799 | B24: 46050 | C24: 61958250101 | D24: BIKTARVY 50-200-25MG TABLET | E24: 30 | F24: 30 | G24: 1 | H24: 4111 | I24: 4111.27 | J24: 0 | K24: 0 | L24: 4111.27 | M24: 0.27 | N24: 004740 | O24: NYM | P24: 9314DA31
A25: 137695 | B25: 46028 | C25: 61958250101 | D25: BIKTARVY 50-200-25MG TABLET | E25: 30 | F25: 30 | G25: 1 | H25: 4111 | I25: 4202.74 | J25: 0 | K25: 0 | L25: 4202.74 | M25: 91.74 | N25: 610490 | O25: RELAYHLTH | P25: ADAP01
A26: 129795 | B26: 46022 | C26: 61958250101 | D26: BIKTARVY 50-200-25MG TABLET | E26: 30 | F26: 30 | G26: 1 | H26: 4111 | I26: 4111.27 | J26: 0 | K26: 0 | L26: 4111.27 | M26: 0.27 | N26: 004740 | O26: NYM | P26: 9314DA31
A27: 129795 | B27: 45994 | C27: 61958250101 | D27: BIKTARVY 50-200-25MG TABLET | E27: 30 | F27: 30 | G27: 1 | H27: 4111 | I27: 4111.21 | J27: 0 | K27: 0 | L27: 4111.21 | M27: 0.21 | N27: 004740 | O27: NYM | P27: 9314DA31
A28: 136231 | B28: 46014 | C28: 00310461612 | D28: BREZTRI AEROSPHERE 160-9-4.8 MCG/ACT INHALATION AEROSOL | E28: 10.7 | F28: 10.7 | G28: 1 | H28: 640 | I28: 646.52 | J28: 0 | K28: 0 | L28: 646.52 | M28: 6.52 | N28: 004740 | O28: NYM | P28: 9314DA31
A29: 136231 | B29: 46042 | C29: 00310461612 | D29: BREZTRI AEROSPHERE 160-9-4.8 MCG/ACT INHALATION AEROSOL | E29: 10.7 | F29: 10.7 | G29: 1 | H29: 640 | I29: 665.62 | J29: 0 | K29: 0 | L29: 665.62 | M29: 25.62 | N29: 004740 | O29: NYM | P29: 9314DA31
A30: 132695 | B30: 45999 | C30: 00310461612 | D30: BREZTRI AEROSPHERE 160-9-4.8 MCG/ACT INHALATION AEROSOL | E30: 10.7 | F30: 32.1 | G30: 3 | H30: 1920 | I30: 1999.41 | J30: 0 | K30: 0 | L30: 1999.41 | M30: 79.41 | N30: 610097 | O30: OPTUM | P30: 9999 | Q30: MPDCSP
A31: 107350 | B31: 46036 | C31: 00310461612 | D31: BREZTRI AEROSPHERE 160-9-4.8 MCG/ACT INHALATION AEROSOL | E31: 10.7 | F31: 10.7 | G31: 1 | H31: 640 | I31: 651.07 | J31: 0 | K31: 0 | L31: 651.07 | M31: 11.07 | N31: 004336 | O31: CAREMARK | P31: MEDDADV | Q31: RX1110
A32: 131361 | B32: 46034 | C32: 00310461612 | D32: BREZTRI AEROSPHERE 160-9-4.8 MCG/ACT INHALATION AEROSOL | E32: 10.7 | F32: 10.7 | G32: 1 | H32: 640 | I32: 651.07 | J32: 0 | K32: 0 | L32: 651.07 | M32: 11.07 | N32: 004336 | O32: CAREMARK | P32: MEDDADV | Q32: RX1110
A33: 110250 | B33: 46072 | C33: 00310737220 | D33: BUDESONIDE-FORMOTEROL FUMARATE 80-4.5MCG/ACT AEROSOL | E33: 10.2 | F33: 30.6 | G33: 3 | H33: 417 | I33: 453.15 | J33: 0 | K33: 1.6 | L33: 454.75 | M33: 37.75 | N33: 610014 | O33: EXPRESS | P33: MEDDPRIME | Q33: 2FFA
A34: 131073 | B34: 46002 | C34: 00310737220 | D34: BUDESONIDE-FORMOTEROL FUMARATE 80-4.5MCG/ACT AEROSOL | E34: 10.2 | F34: 10.2 | G34: 1 | H34: 139 | I34: 156.06 | J34: 0 | K34: 0 | L34: 156.06 | M34: 17.06 | N34: 015574 | O34: MEDIMP | P34: ASPROD1 | Q34: VNS01
A35: 137969 | B35: 46029 | C35: 00310737220 | D35: BUDESONIDE-FORMOTEROL FUMARATE 80-4.5MCG/ACT AEROSOL | E35: 10.2 | F35: 10.2 | G35: 1 | H35: 139 | I35: 135.1 | J35: 0 | K35: 6 | L35: 141.1 | M35: 2.1 | N35: 004336 | O35: CAREMARK | P35: ADV | Q35: RX1103
A36: 134075 | B36: 45997 | C36: 00310737220 | D36: BUDESONIDE-FORMOTEROL FUMARATE 80-4.5MCG/ACT AEROSOL | E36: 10.2 | F36: 10.2 | G36: 1 | H36: 139 | I36: 190.61 | J36: 0 | K36: 0 | L36: 190.61 | M36: 51.61 | N36: 610502 | O36: CAREMARK | P36: MEDDAET | Q36: RXAETD
A37: 131073 | B37: 46030 | C37: 00310737220 | D37: BUDESONIDE-FORMOTEROL FUMARATE 80-4.5MCG/ACT AEROSOL | E37: 10.2 | F37: 10.2 | G37: 1 | H37: 139 | I37: 154.41 | J37: 0 | K37: 1.6 | L37: 156.01 | M37: 17.01 | N37: 015574 | O37: MEDIMP | P37: ASPROD1 | Q37: VNS01
A38: 131073 | B38: 46058 | C38: 00310737220 | D38: BUDESONIDE-FORMOTEROL FUMARATE 80-4.5MCG/ACT AEROSOL | E38: 10.2 | F38: 10.2 | G38: 1 | H38: 139 | I38: 154.41 | J38: 0 | K38: 1.6 | L38: 156.01 | M38: 17.01 | N38: 015574 | O38: MEDIMP | P38: ASPROD1 | Q38: VNS01
A39: 137969 | B39: 46057 | C39: 00310737220 | D39: BUDESONIDE-FORMOTEROL FUMARATE 80-4.5MCG/ACT AEROSOL | E39: 10.2 | F39: 10.2 | G39: 1 | H39: 139 | I39: 140.1 | J39: 0 | K39: 1 | L39: 141.1 | M39: 2.1 | N39: 004336 | O39: CAREMARK | P39: ADV | Q39: RX1103
A40: 137336 | B40: 46024 | C40: 00310737220 | D40: BUDESONIDE-FORMOTEROL FUMARATE 80-4.5MCG/ACT AEROSOL | E40: 10.2 | F40: 10.2 | G40: 1 | H40: 139 | I40: 80.85 | J40: 357.59 | K40: 15 | L40: 453.44 | M40: 314.44 | N40: 020099 | O40: CAREMARK | P40: WG | Q40: WLDA
...

Sheet MFP Drugs - RX
A1: MFP DRUGS
A2: RX | B2: Fill Date | C2: NDC | D2: Drug Name | E2: Pkg Size | F2: Qty Filled | G2: Package billed | H2: Kinray Unit Price | I2: Kinray Final Price | J2: Ins Paid Plan 1 | K2: Ins Paid Plan 2 | L2: SDRA Amt | M2: COPAY | N2: Winning Ins Paid | O2: Total Collected | P2: Difference | Q2: BIN | R2: Processor | S2: PCN | T2: Group
A3: 137336 | B3: 46024 | C3: 00310737220 | D3: BUDESONIDE-FORMOTEROL FUMARATE 80-4.5MCG/ACT AEROSOL | E3: 10.2 | F3: 10.2 | G3: 1 | H3: 139 | I3: 139 | J3: 80.85 | K3: 0 | L3: 357.59 | M3: 15 | N3: 80.85 | O3: 453.44 | P3: 314.44 | Q3: 020099 | R3: CAREMARK | S3: WG | T3: WLDA
A4: 132589 | B4: 46073 | C4: 00003089321 | D4: ELIQUIS 2.5MG TAB | E4: 60 | F4: 180 | G4: 3 | H4: 336 | I4: 1008 | J4: 740.87 | K4: 0 | L4: 290.66 | M4: 4.9 | N4: 740.87 | O4: 1036.43 | P4: 28.43 | Q4: 004336 | R4: CAREMARK | S4: MEDDADV | T4: RX1110
A5: 120419 | B5: 46066 | C5: 00003089321 | D5: ELIQUIS 2.5MG TAB | E5: 60 | F5: 180 | G5: 3 | H5: 336 | I5: 1008 | J5: 745.77 | K5: 0 | L5: 290.66 | M5: 0 | N5: 745.77 | O5: 1036.43 | P5: 28.43 | Q5: 004336 | R5: CAREMARK | S5: MEDDADV | T5: RX8585
A6: 123970 | B6: 46062 | C6: 00003089321 | D6: ELIQUIS 2.5MG TAB | E6: 60 | F6: 60 | G6: 1 | H6: 336 | I6: 336 | J6: 243.56 | K6: 0 | L6: 96.89 | M6: 4.9 | N6: 243.56 | O6: 345.35 | P6: 9.35 | Q6: 004336 | R6: CAREMARK | S6: MEDDADV | T6: RX8541
A7: 115384 | B7: 46036 | C7: 00003089321 | D7: ELIQUIS 2.5MG TAB | E7: 60 | F7: 180 | G7: 3 | H7: 333 | I7: 999 | J7: 745.77 | K7: 0 | L7: 290.66 | M7: 0 | N7: 745.77 | O7: 1036.43 | P7: 37.43 | Q7: 004336 | R7: CAREMARK | S7: MEDDADV | T7: RX1110
A8: 123970 | B8: 46034 | C8: 00003089321 | D8: ELIQUIS 2.5MG TAB | E8: 60 | F8: 60 | G8: 1 | H8: 333 | I8: 333 | J8: 243.56 | K8: 0 | L8: 96.89 | M8: 4.9 | N8: 243.56 | O8: 345.35 | P8: 12.35 | Q8: 004336 | R8: CAREMARK | S8: MEDDADV | T8: RX8541
A9: 133556 | B9: 46077 | C9: 00003089421 | D9: ELIQUIS 5MG TAB | E9: 60 | F9: 60 | G9: 1 | H9: 336 | I9: 336 | J9: 218.46 | K9: 0 | L9: 96.89 | M9: 30 | N9: 218.46 | O9: 345.35 | P9: 9.35 | Q9: 004336 | R9: CAREMARK | S9: MEDDADV | T9: RXCVSD
A10: 143964 | B10: 46072 | C10: 00003089421 | D10: ELIQUIS 5MG TAB | E10: 60 | F10: 180 | G10: 3 | H10: 336 | I10: 1008 | J10: 750.8 | K10: 0 | L10: 290.66 | M10: 0 | N10: 750.8 | O10: 1041.46 | P10: 33.46 | Q10: 015574 | R10: MEDIMP | S10: ASPROD1 | T10: VNS01
A11: 143572 | B11: 46070 | C11: 00003089421 | D11: ELIQUIS 5MG TAB | E11: 60 | F11: 180 | G11: 3 | H11: 336 | I11: 1008 | J11: 740.87 | K11: 0 | L11: 290.66 | M11: 4.9 | N11: 740.87 | O11: 1036.43 | P11: 28.43 | Q11: 004336 | R11: CAREMARK | S11: MEDDADV | T11: RX1110
A12: 142332 | B12: 46062 | C12: 00003089421 | D12: ELIQUIS 5MG TAB | E12: 60 | F12: 180 | G12: 3 | H12: 336 | I12: 1008 | J12: 740.87 | K12: 0 | L12: 290.66 | M12: 4.9 | N12: 740.87 | O12: 1036.43 | P12: 28.43 | Q12: 004336 | R12: CAREMARK | S12: MEDDADV | T12: RX1110
A13: 130641 | B13: 46059 | C13: 00003089421 | D13: ELIQUIS 5MG TAB | E13: 60 | F13: 180 | G13: 3 | H13: 336 | I13: 1008 | J13: 740.87 | K13: 0 | L13: 290.66 | M13: 4.9 | N13: 740.87 | O13: 1036.43 | P13: 28.43 | Q13: 004336 | R13: CAREMARK | S13: MEDDADV | T13: RX1110
A14: 141828 | B14: 46059 | C14: 00003089421 | D14: ELIQUIS 5MG TAB | E14: 60 | F14: 180 | G14: 3 | H14: 336 | I14: 1008 | J14: 740.87 | K14: 0 | L14: 290.66 | M14: 4.9 | N14: 740.87 | O14: 1036.43 | P14: 28.43 | Q14: 004336 | R14: CAREMARK | S14: MEDDADV | T14: RX1110
... A34: 141159 | B34: 46052 | C34: 00310621030 | D34: FARXIGA 10MG TABLET | E34: 30 | F34: 90 | G34: 3 | H34: 365 | I34: 1095 | J34: 542.82 | K34: 0 | L34: 588.7 | M34: 1.6 | N34: 542.82 | O34: 1133.12 | P34: 38.12 | Q34: 004336 | R34: CAREMARK | S34: MEDDADV | T34: RX1110
A35: 129765 | B35: 46050 | C35: 00310621030 | D35: FARXIGA 10MG TABLET | E35: 30 | F35: 90 | G35: 3 | H35: 365 | I35: 1095 | J35: 544.55 | K35: 0 | L35: 588.7 | M35: 4.9 | N35: 544.55 | O35: 1138.15 | P35: 43.15 | Q35: 015574 | R35: MEDIMP | S35: ASPROD1
A36: 140829 | B36: 46050 | C36: 00310621030 | D36: FARXIGA 10MG TABLET | E36: 30 | F36: 90 | G36: 3 | H36: 365 | I36: 1095 | J36: 542.82 | K36: 0 | L36: 588.7 | M36: 1.6 | N36: 542.82 | O36: 1133.12 | P36: 38.12 | Q36: 004336 | R36: CAREMARK | S36: MEDDADV | T36: RX1110
A37: 140537 | B37: 46048 | C37: 00310621030 | D37: FARXIGA 10MG TABLET | E37: 30 | F37: 90 | G37: 3 | H37: 365 | I37: 1095 | J37: 430.1 | K37: 0 | L37: 588.7 | M37: 114.32 | N37: 430.1 | O37: 1133.12 | P37: 38.12 | Q37: 004336 | R37: CAREMARK | S37: MEDDADV | T37: RX1110
A38: 140180 | B38: 46044 | C38: 00310621030 | D38: FARXIGA 10MG TABLET | E38: 30 | F38: 90 | G38: 3 | H38: 365 | I38: 1095 | J38: 542.82 | K38: 0 | L38: 588.7 | M38: 1.6 | N38: 542.82 | O38: 1133.12 | P38: 38.12 | Q38: 004336 | R38: CAREMARK | S38: MEDDADV | T38: RX1110
A39: 128113 | B39: 46038 | C39: 00310621030 | D39: FARXIGA 10MG TABLET | E39: 30 | F39: 90 | G39: 3 | H39: 365 | I39: 1095 | J39: 542.82 | K39: 0 | L39: 588.7 | M39: 1.6 | N39: 542.82 | O39: 1133.12 | P39: 38.12 | Q39: 004336 | R39: CAREMARK | S39: MEDDADV | T39: RX1110
A40: 126072 | B40: 46035 | C40: 00310621030 | D40: FARXIGA 10MG TABLET | E40: 30 | F40: 90 | G40: 3 | H40: 365 | I40: 1095 | J40: 544.42 | K40: 0 | L40: 588.7 | M40: 0 | N40: 544.42 | O40: 1133.12 | P40: 38.12 | Q40: 004336 | R40: CAREMARK | S40: MEDDADV | T40: RX1110
A41: 138948 | B41: 46035 | C41: 00310621030 | D41: FARXIGA 10MG TABLET | E41: 30 | F41: 90 | G41: 3 | H41: 365 | I41: 1095 | J41: 545.76 | K41: 0 | L41: 588.7 | M41: 0 | N41: 545.76 | O41: 1134.46 | P41: 39.46 | Q41: 610014 | R41: EXPRESS | S41: MEDDPRIME | T41: 2FFA
A42: 138950 | B42: 46035 | C42: 00310621030 | D42: FARXIGA 10MG TABLET | E42: 30 | F42: 90 | G42: 3 | H42: 365 | I42: 1095 | J42: 549.45 | K42: 0 | L42: 588.7 | M42: 0 | N42: 549.45 | O42: 1138.15 | P42: 43.15 | Q42: 015574 | R42: MEDIMP | S42: ASPROD1 | T42: VNS01
A43: 121812 | B43: 46024 | C43: 00310621030 | D43: FARXIGA 10MG TABLET | E43: 30 | F43: 30 | G43: 1 | H43: 365 | I43: 365 | J43: 181.38 | K43: 0 | L43: 196.23 | M43: 4.9 | N43: 181.38 | O43: 382.51 | P43: 17.51 | Q43: 015574 | R43: MEDIMP | S43: ASPROD1 | T43: VNS01
A44: 139593 | B44: 46041 | C44: 00310620530 | D44: FARXIGA 5MG TABLET | E44: 30 | F44: 90 | G44: 3 | H44: 365 | I44: 1095 | J44: 544.42 | K44: 0 | L44: 588.7 | M44: 0 | N44: 544.42 | O44: 1133.12 | P44: 38.12 | Q44: 004336 | R44: CAREMARK | S44: MEDDADV | T44: RX8585
A45: 135058 | B45: 46035 | C45: 00310620530 | D45: FARXIGA 5MG TABLET | E45: 30 | F45: 30 | G45: 1 | H45: 365 | I45: 365 | J45: 181.35 | K45: 0 | L45: 196.23 | M45: 0 | N45: 181.35 | O45: 377.58 | P45: 12.58 | Q45: 004336 | R45: CAREMARK | S45: MEDDADV | T45: RX1110
A46: 143116 | B46: 46065 | C46: 00006027731 | D46: JANUVIA 100MG TAB | E46: 30 | F46: 90 | G46: 3 | H46: 321 | I46: 963 | J46: 346.47 | K46: 0 | L46: 638.29 | M46: 4.9 | N46: 346.47 | O46: 989.66 | P46: 26.66 | Q46: 004336 | R46: CAREMARK | S46: MEDDADV | T46: RX1110
A47: 138331 | B47: 46064 | C47: 00006027731 | D47: JANUVIA 100MG TAB | E47: 30 | F47: 90 | G47: 3 | H47: 321 | I47: 963 | J47: 351.37 | K47: 0 | L47: 638.29 | M47: 0 | N47: 351.37 | O47: 989.66 | P47: 26.66 | Q47: 004336 | R47: CAREMARK | S47: MEDDADV | T47: RX8585
... A58: 115240 | B58: 46027 | C58: 00006027731 | D58: JANUVIA 100MG TAB | E58: 30 | F58: 90 | G58: 3 | H58: 318 | I58: 954 | J58: 351.37 | K58: 0 | L58: 638.29 | M58: 0 | N58: 351.37 | O58: 989.66 | P58: 35.66 | Q58: 004336 | R58: CAREMARK | S58: MEDDADV | T58: RX1110
A59: 133674 | B59: 46027 | C59: 00006027731 | D59: JANUVIA 100MG TAB | E59: 30 | F59: 90 | G59: 3 | H59: 318 | I59: 954 | J59: 356.4 | K59: 0 | L59: 638.29 | M59: 0 | N59: 356.4 | O59: 994.69 | P59: 40.69 | Q59: 015574 | R59: MEDIMP | S59: ASPROD1
A60: 137417 | B60: 46027 | C60: 00006027731 | D60: JANUVIA 100MG TAB | E60: 30 | F60: 90 | G60: 3 | H60: 318 | I60: 954 | J60: 346.47 | K60: 0 | L60: 638.29 | M60: 4.9 | N60: 346.47 | O60: 989.66 | P60: 35.66 | Q60: 004336 | R60: CAREMARK | S60: MEDDADV | T60: RX1110
A61: 137451 | B61: 46027 | C61: 00006027731 | D61: JANUVIA 100MG TAB | E61: 30 | F61: 90 | G61: 3 | H61: 318 | I61: 954 | J61: 346.47 | K61: 0 | L61: 638.29 | M61: 4.9 | N61: 346.47 | O61: 989.66 | P61: 35.66 | Q61: 004336 | R61: CAREMARK | S61: MEDDADV | T61: RX1110
A62: 144507 | B62: 46077 | C62: 00006022131 | D62: JANUVIA 25MG TABLET | E62: 30 | F62: 30 | G62: 1 | H62: 318 | I62: 318 | J62: 127.74 | K62: 0 | L62: 212.76 | M62: 0 | N62: 127.74 | O62: 340.5 | P62: 22.5 | Q62: 017010 | R62: EXPRESS | S62: CIMCARE | T62: CIGPDPRX
A63: 140578 | B63: 46049 | C63: 00006022131 | D63: JANUVIA 25MG TABLET | E63: 30 | F63: 30 | G63: 1 | H63: 318 | I63: 318 | J63: 127.74 | K63: 0 | L63: 212.76 | M63: 0 | N63: 127.74 | O63: 340.5 | P63: 22.5 | Q63: 017010 | R63: EXPRESS | S63: CIMCARE | T63: CIGPDPRX
A64: 116072 | B64: 46077 | C64: 00006011231 | D64: JANUVIA 50MG TABLET | E64: 30 | F64: 30 | G64: 1 | H64: 321 | I64: 321 | J64: 113.34 | K64: 0 | L64: 212.76 | M64: 4.9 | N64: 113.34 | O64: 331 | P64: 10 | Q64: 610014 | R64: EXPRESS | S64: MEDDPRIME | T64: 2FFA
A65: 131732 | B65: 46069 | C65: 00006011231 | D65: JANUVIA 50MG TABLET | E65: 30 | F65: 90 | G65: 3 | H65: 321 | I65: 963 | J65: 316.71 | K65: 0 | L65: 638.29 | M65: 45 | N65: 316.71 | O65: 1000 | P65: 37 | Q65: 610455 | R65: PRIMECAPRX | S65: NY4000 | T65: MAPD
A66: 142710 | B66: 46064 | C66: 00006011231 | D66: JANUVIA 50MG TABLET | E66: 30 | F66: 90 | G66: 3 | H66: 321 | I66: 963 | J66: 351.37 | K66: 0 | L66: 638.29 | M66: 0 | N66: 351.37 | O66: 989.66 | P66: 26.66 | Q66: 004336 | R66: CAREMARK | S66: MEDDADV | T66: RX1110
A67: 142886 | B67: 46064 | C67: 00006011231 | D67: JANUVIA 50MG TABLET | E67: 30 | F67: 60 | G67: 2 | H67: 321 | I67: 642 | J67: 234.77 | K67: 0 | L67: 425.53 | M67: 0 | N67: 234.77 | O67: 660.3 | P67: 18.3 | Q67: 015599 | R67: ARG/HUM | S67: 05440000
A68: 142289 | B68: 46062 | C68: 00006011231 | D68: JANUVIA 50MG TABLET | E68: 30 | F68: 90 | G68: 3 | H68: 321 | I68: 963 | J68: 351.37 | K68: 0 | L68: 638.29 | M68: 0 | N68: 351.37 | O68: 989.66 | P68: 26.66 | Q68: 004336 | R68: CAREMARK | S68: MEDDADV | T68: RX1110
A69: 116072 | B69: 46049 | C69: 00006011231 | D69: JANUVIA 50MG TABLET | E69: 30 | F69: 30 | G69: 1 | H69: 318 | I69: 318 | J69: 113.34 | K69: 0 | L69: 212.76 | M69: 4.9 | N69: 113.34 | O69: 331 | P69: 13 | Q69: 610014 | R69: EXPRESS | S69: MEDDPRIME | T69: 2FFA
...

Sheet Summary
A1: Summary
A2: Summary of Hil for the date range hh
A3: Metric | B3: ALL_PBM | C3: ARG/HUM | D3: CAREMARK | E3: EXPRESS | F3: FDS | G3: MEDIMP | H3: NYM | I3: OPTUM | J3: PRIMECAPRX | K3: RELAYHLTH
A4: Insurance $(BestRX) | B4: =SUM('Processed Data'!AK4:AK208) | C4: =SUM('Processed Data'!AL4:AL208) | D4: =SUM('Processed Data'!AM4:AM208) | E4: =SUM('Processed Data'!AN4:AN208) | F4: =SUM('Processed Data'!AO4:AO208) | G4: =SUM('Processed Data'!AP4:AP208) | H4: =SUM('Processed Data'!AQ4:AQ208) | I4: =SUM('Processed Data'!AR4:AR208) | ... K4: =SUM('Processed Data'!AT4:AT208)
A5: 100% $$ Purchased (Kinray) | B5: =SUM('Processed Data'!AU4:AU208) | C5: =SUM('Processed Data'!AV4:AV208) | D5: =SUM('Processed Data'!AW4:AW208) | E5: =SUM('Processed Data'!AX4:AX208) | F5: =SUM('Processed Data'!AY4:AY208) | G5: =SUM('Processed Data'!AZ4:AZ208) | H5: =SUM('Processed Data'!BA4:BA208) | I5: =SUM('Processed Data'!BB4:BB208) | ... K5: =SUM('Processed Data'!BD4:BD208)
A6: Net (Paid − Purchased) | B6: =SUM('Processed Data'!BE4:BE208) | C6: =SUM('Processed Data'!BF4:BF208) | D6: =SUM('Processed Data'!BG4:BG208) | E6: =SUM('Processed Data'!BH4:BH208) | F6: =SUM('Processed Data'!BI4:BI208) | G6: =SUM('Processed Data'!BJ4:BJ208) | H6: =SUM('Processed Data'!BK4:BK208) | I6: =SUM('Processed Data'!BL4:BL208) | ... K6: =SUM('Processed Data'!BN4:BN208)
A7: Needs to Ordered Sheet, Insurance-wise Order Estimate ($) | B7: =IFERROR(INDEX('Needs to be ordered - All'!$R$3:$R$103,MATCH("ALL_PBM_D", 'Needs to be ordered - All'!$Q$3:$Q$103, 0)), 0) | C7: =IFERROR(INDEX('Needs to be ordered - All'!$R$3:$R$103,MATCH("ARG/HUM_D", 'Needs to be ordered - All'!$Q$3:$Q$103, 0)), 0) | D7: =IFERROR(INDEX('Needs to be ordered - All'!$R$3:$R$103,MATCH("CAREMARK_D", 'Needs to be ordered - All'!$Q$3:$Q$103, 0)), 0) | E7: =IFERROR(INDEX('Needs to be ordered - All'!$R$3:$R$103,MATCH("EXPRESS_D", 'Needs to be ordered - All'!$Q$3:$Q$103, 0)), 0) | F7: =IFERROR(INDEX('Needs to be ordered - All'!$R$3:$R$103,MATCH("FDS_D", 'Needs to be ordered - All'!$Q$3:$Q$103, 0)), 0) | G7: =IFERROR(INDEX('Needs to be ordered - All'!$R$3:$R$103,MATCH("MEDIMP_D", 'Needs to be ordered - All'!$Q$3:$Q$103, 0)), 0) | H7: =IFERROR(INDEX('Needs to be ordered - All'!$R$3:$R$103,MATCH("NYM_D", 'Needs to be ordered - All'!$Q$3:$Q$103, 0)), 0) | I7: =IFERROR(INDEX('Needs to be ordered - All'!$R$3:$R$103,MATCH("OPTUM_D", 'Needs to be ordered - All'!$Q$3:$Q$103, 0)), 0) | J7: =IFERROR(INDEX('Needs to be ordered - All'!$R$3:$R$103,MATCH("PRIMECAPRX_D", 'Needs to be ordered - All'!$Q$3:$Q$103, 0)), 0) | K7: =IFERROR(INDEX('Needs to be ordered - All'!$R$3:$R$103,MATCH("RELAYHLTH_D", 'Needs to be ordered - All'!$Q$3:$Q$103, 0)), 0)
